Workbook

Sheet Actuals
C1: 2026 Actuals
A3: Guest = 1 | B3: Player | C3: Week 1 | D3: Week 2 | E3: Week 3 | F3: Week 4 | G3: Week 5 | H3: Week 6 | I3: Week 7 | J3: Week 8 | K3: Week 9 | L3: Week 10 | M3: Week 11 | N3: Week 12 | O3: Week 13 | P3: Week 14 | Q3: Week 15 | R3: Week 16 | S3: Events Played | T3: Total Strokes | U3: Avg Score
B4: =ModifiedAvg!A4 -> Adrian C | S4: =count(C4:R4) -> 0 | T4: =sum(C4:R4) -> 0 | U4: =iferror(T4/S4,"NA") -> NA
B5: =ModifiedAvg!A5 -> Alan D | S5: =count(C5:R5) -> 0 | T5: =sum(C5:R5) -> 0 | U5: =iferror(T5/S5,"NA") -> NA
B6: =ModifiedAvg!A6 -> Baxter C | S6: =count(C6:R6) -> 0 | T6: =sum(C6:R6) -> 0 | U6: =iferror(T6/S6,"NA") -> NA
B7: =ModifiedAvg!A7 -> Bill Morton | S7: =count(C7:R7) -> 0 | T7: =sum(C7:R7) -> 0 | U7: =iferror(T7/S7,"NA") -> NA
B8: =ModifiedAvg!A8 -> Brian M | C8: 39 | D8: 39 | E8: 42 | S8: =count(C8:R8) -> 3 | T8: =sum(C8:R8) -> 120 | U8: =iferror(T8/S8,"NA") -> 40
B9: =ModifiedAvg!A9 -> Bruce Marburger | C9: 51 | S9: =count(C9:R9) -> 1 | T9: =sum(C9:R9) -> 51 | U9: =iferror(T9/S9,"NA") -> 51
B10: =ModifiedAvg!A10 -> Cole L | S10: =count(C10:R10) -> 0 | T10: =sum(C10:R10) -> 0 | U10: =iferror(T10/S10,"NA") -> NA
A11: 1 | B11: =ModifiedAvg!A11 -> Danny C | S11: =count(C11:R11) -> 0 | T11: =sum(C11:R11) -> 0 | U11: =iferror(T11/S11,"NA") -> NA
A12: 1 | B12: =ModifiedAvg!A12 -> Eddie G | E12: 52 | S12: =count(C12:R12) -> 1 | T12: =sum(C12:R12) -> 52 | U12: =iferror(T12/S12,"NA") -> 52
B13: =ModifiedAvg!A13 -> Grant G | S13: =count(C13:R13) -> 0 | T13: =sum(C13:R13) -> 0 | U13: =iferror(T13/S13,"NA") -> NA
B14: =ModifiedAvg!A14 -> Jeff H | S14: =count(C14:R14) -> 0 | T14: =sum(C14:R14) -> 0 | U14: =iferror(T14/S14,"NA") -> NA
B15: =ModifiedAvg!A15 -> Jenna T | S15: =count(C15:R15) -> 0 | T15: =sum(C15:R15) -> 0 | U15: =iferror(T15/S15,"NA") -> NA
A16: 1 | B16: =ModifiedAvg!A16 -> Jeremy H | S16: =count(C16:R16) -> 0 | T16: =sum(C16:R16) -> 0 | U16: =iferror(T16/S16,"NA") -> NA
B17: =ModifiedAvg!A17 -> Jeremy S | S17: =count(C17:R17) -> 0 | T17: =sum(C17:R17) -> 0 | U17: =iferror(T17/S17,"NA") -> NA
B18: =ModifiedAvg!A18 -> Jon L | C18: 48 | D18: 43 | E18: 45 | S18: =count(C18:R18) -> 3 | T18: =sum(C18:R18) -> 136 | U18: =iferror(T18/S18,"NA") -> 45.333333
B19: =ModifiedAvg!A19 -> Jonah R | D19: 47 | S19: =count(C19:R19) -> 1 | T19: =sum(C19:R19) -> 47 | U19: =iferror(T19/S19,"NA") -> 47
B20: =ModifiedAvg!A20 -> Jordan V | S20: =count(C20:R20) -> 0 | T20: =sum(C20:R20) -> 0 | U20: =iferror(T20/S20,"NA") -> NA
A21: 1 | B21: =ModifiedAvg!A21 -> Kyle N | C21: 41 | D21: 47 | E21: 38 | S21: =count(C21:R21) -> 3 | T21: =sum(C21:R21) -> 126 | U21: =iferror(T21/S21,"NA") -> 42
B22: =ModifiedAvg!A22 -> Laura L | S22: =count(C22:R22) -> 0 | T22: =sum(C22:R22) -> 0 | U22: =iferror(T22/S22,"NA") -> NA
B23: =ModifiedAvg!A23 -> Luke W | E23: 36 | S23: =count(C23:R23) -> 1 | T23: =sum(C23:R23) -> 36 | U23: =iferror(T23/S23,"NA") -> 36
B24: =ModifiedAvg!A24 -> Marc C | C24: 34 | D24: 39 | S24: =count(C24:R24) -> 2 | T24: =sum(C24:R24) -> 73 | U24: =iferror(T24/S24,"NA") -> 36.5
B25: =ModifiedAvg!A25 -> Mark M | C25: 45 | D25: 46 | E25: 46 | S25: =count(C25:R25) -> 3 | T25: =sum(C25:R25) -> 137 | U25: =iferror(T25/S25,"NA") -> 45.666667
B26: =ModifiedAvg!A26 -> Martin R | S26: =count(C26:R26) -> 0 | T26: =sum(C26:R26) -> 0 | U26: =iferror(T26/S26,"NA") -> NA
B27: =ModifiedAvg!A27 -> Minji S | S27: =count(C27:R27) -> 0 | T27: =sum(C27:R27) -> 0 | U27: =iferror(T27/S27,"NA") -> NA
B28: =ModifiedAvg!A28 -> Nate R | C28: 53 | D28: 54 | E28: 53 | S28: =count(C28:R28) -> 3 | T28: =sum(C28:R28) -> 160 | U28: =iferror(T28/S28,"NA") -> 53.333333
B29: =ModifiedAvg!A29 -> Phil J | S29: =count(C29:R29) -> 0 | T29: =sum(C29:R29) -> 0 | U29: =iferror(T29/S29,"NA") -> NA
B30: =ModifiedAvg!A30 -> Preston C | C30: 38 | D30: 43 | E30: 40 | S30: =count(C30:R30) -> 3 | T30: =sum(C30:R30) -> 121 | U30: =iferror(T30/S30,"NA") -> 40.333333
B31: =ModifiedAvg!A31 -> Rich | E31: 44 | S31: =count(C31:R31) -> 1 | T31: =sum(C31:R31) -> 44 | U31: =iferror(T31/S31,"NA") -> 44
B32: =ModifiedAvg!A32 -> Russ B | S32: =count(C32:R32) -> 0 | T32: =sum(C32:R32) -> 0 | U32: =iferror(T32/S32,"NA") -> NA
B33: =ModifiedAvg!A33 -> Russ H | S33: =count(C33:R33) -> 0 | T33: =sum(C33:R33) -> 0 | U33: =iferror(T33/S33,"NA") -> NA
A34: 1 | B34: =ModifiedAvg!A34 -> Ryan R | S34: =count(C34:R34) -> 0 | T34: =sum(C34:R34) -> 0 | U34: =iferror(T34/S34,"NA") -> NA
B35: =ModifiedAvg!A35 -> Scott M | S35: =count(C35:R35) -> 0 | T35: =sum(C35:R35) -> 0 | U35: =iferror(T35/S35,"NA") -> NA
B36: =ModifiedAvg!A36 -> Seth A | S36: =count(C36:R36) -> 0 | T36: =sum(C36:R36) -> 0 | U36: =iferror(T36/S36,"NA") -> NA
B37: =ModifiedAvg!A37 -> Simon R | C37: 36 | S37: =count(C37:R37) -> 1 | T37: =sum(C37:R37) -> 36 | U37: =iferror(T37/S37,"NA") -> 36
B38: =ModifiedAvg!A38 -> Steve S | S38: =count(C38:R38) -> 0 | T38: =sum(C38:R38) -> 0 | U38: =iferror(T38/S38,"NA") -> NA
B39: =ModifiedAvg!A39 -> Tanner Brown | D39: 52 | S39: =count(C39:R39) -> 1 | T39: =sum(C39:R39) -> 52 | U39: =iferror(T39/S39,"NA") -> 52
B40: =ModifiedAvg!A40 -> Tanner Buechele | S40: =count(C40:R40) -> 0 | T40: =sum(C40:R40) -> 0 | U40: =iferror(T40/S40,"NA") -> NA
B41: =ModifiedAvg!A41 -> Thomas Y | S41: =count(C41:R41) -> 0 | T41: =sum(C41:R41) -> 0 | U41: =iferror(T41/S41,"NA") -> NA
...

Sheet NetScores
B1: 2026 Weekly Net Score
A3: Player | B3: Week 1 | C3: Week 2 | D3: Week 3 | E3: Week 4 | F3: Week 5 | G3: Week 6 | H3: Week 7 | I3: Week 8 | J3: Week 9 | K3: Week 10 | L3: Week 11 | M3: Week 12 | N3: Week 13 | O3: Week 14 | P3: Week 15 | Q3: Week 16
A4: =Actuals!B4 -> Adrian C | B4: =if(Actuals!C4 = "", "",Actuals!C4 + Strokes!B4) | C4: =if(Actuals!D4 = "", "",Actuals!D4 + Strokes!C4) | D4: =if(Actuals!E4 = "", "",Actuals!E4 + Strokes!D4) | E4: =if(Actuals!F4 = "", "",Actuals!F4 + Strokes!E4) | F4: =if(Actuals!G4 = "", "",Actuals!G4 + Strokes!F4) | G4: =if(Actuals!H4 = "", "",Actuals!H4 + Strokes!G4) | H4: =if(Actuals!I4 = "", "",Actuals!I4 + Strokes!H4) | I4: =if(Actuals!J4 = "", "",Actuals!J4 + Strokes!I4) | ... Q4: =if(Actuals!R4 = "", "",Actuals!R4 + Strokes!Q4)
A5: =Actuals!B5 -> Alan D | B5: =if(Actuals!C5 = "", "",Actuals!C5 + Strokes!B5) | C5: =if(Actuals!D5 = "", "",Actuals!D5 + Strokes!C5) | D5: =if(Actuals!E5 = "", "",Actuals!E5 + Strokes!D5) | E5: =if(Actuals!F5 = "", "",Actuals!F5 + Strokes!E5) | F5: =if(Actuals!G5 = "", "",Actuals!G5 + Strokes!F5) | G5: =if(Actuals!H5 = "", "",Actuals!H5 + Strokes!G5) | H5: =if(Actuals!I5 = "", "",Actuals!I5 + Strokes!H5) | I5: =if(Actuals!J5 = "", "",Actuals!J5 + Strokes!I5) | ... Q5: =if(Actuals!R5 = "", "",Actuals!R5 + Strokes!Q5)
A6: =Actuals!B6 -> Baxter C | B6: =if(Actuals!C6 = "", "",Actuals!C6 + Strokes!B6) | C6: =if(Actuals!D6 = "", "",Actuals!D6 + Strokes!C6) | D6: =if(Actuals!E6 = "", "",Actuals!E6 + Strokes!D6) | E6: =if(Actuals!F6 = "", "",Actuals!F6 + Strokes!E6) | F6: =if(Actuals!G6 = "", "",Actuals!G6 + Strokes!F6) | G6: =if(Actuals!H6 = "", "",Actuals!H6 + Strokes!G6) | H6: =if(Actuals!I6 = "", "",Actuals!I6 + Strokes!H6) | I6: =if(Actuals!J6 = "", "",Actuals!J6 + Strokes!I6) | ... Q6: =if(Actuals!R6 = "", "",Actuals!R6 + Strokes!Q6)
A7: =Actuals!B7 -> Bill Morton | B7: =if(Actuals!C7 = "", "",Actuals!C7 + Strokes!B7) | C7: =if(Actuals!D7 = "", "",Actuals!D7 + Strokes!C7) | D7: =if(Actuals!E7 = "", "",Actuals!E7 + Strokes!D7) | E7: =if(Actuals!F7 = "", "",Actuals!F7 + Strokes!E7) | F7: =if(Actuals!G7 = "", "",Actuals!G7 + Strokes!F7) | G7: =if(Actuals!H7 = "", "",Actuals!H7 + Strokes!G7) | H7: =if(Actuals!I7 = "", "",Actuals!I7 + Strokes!H7) | I7: =if(Actuals!J7 = "", "",Actuals!J7 + Strokes!I7) | ... Q7: =if(Actuals!R7 = "", "",Actuals!R7 + Strokes!Q7)
A8: =Actuals!B8 -> Brian M | B8: =if(Actuals!C8 = "", "",Actuals!C8 + Strokes!B8) -> 32.7 | C8: =if(Actuals!D8 = "", "",Actuals!D8 + Strokes!C8) -> 34.7 | D8: =if(Actuals!E8 = "", "",Actuals!E8 + Strokes!D8) -> 37.6 | E8: =if(Actuals!F8 = "", "",Actuals!F8 + Strokes!E8) | F8: =if(Actuals!G8 = "", "",Actuals!G8 + Strokes!F8) | G8: =if(Actuals!H8 = "", "",Actuals!H8 + Strokes!G8) | H8: =if(Actuals!I8 = "", "",Actuals!I8 + Strokes!H8) | I8: =if(Actuals!J8 = "", "",Actuals!J8 + Strokes!I8) | ... Q8: =if(Actuals!R8 = "", "",Actuals!R8 + Strokes!Q8)
A9: =Actuals!B9 -> Bruce Marburger | B9: =if(Actuals!C9 = "", "",Actuals!C9 + Strokes!B9) -> 38.1 | C9: =if(Actuals!D9 = "", "",Actuals!D9 + Strokes!C9) | D9: =if(Actuals!E9 = "", "",Actuals!E9 + Strokes!D9) | E9: =if(Actuals!F9 = "", "",Actuals!F9 + Strokes!E9) | F9: =if(Actuals!G9 = "", "",Actuals!G9 + Strokes!F9) | G9: =if(Actuals!H9 = "", "",Actuals!H9 + Strokes!G9) | H9: =if(Actuals!I9 = "", "",Actuals!I9 + Strokes!H9) | I9: =if(Actuals!J9 = "", "",Actuals!J9 + Strokes!I9) | ... Q9: =if(Actuals!R9 = "", "",Actuals!R9 + Strokes!Q9)
A10: =Actuals!B10 -> Cole L | B10: =if(Actuals!C10 = "", "",Actuals!C10 + Strokes!B10) | C10: =if(Actuals!D10 = "", "",Actuals!D10 + Strokes!C10) | D10: =if(Actuals!E10 = "", "",Actuals!E10 + Strokes!D10) | E10: =if(Actuals!F10 = "", "",Actuals!F10 + Strokes!E10) | F10: =if(Actuals!G10 = "", "",Actuals!G10 + Strokes!F10) | G10: =if(Actuals!H10 = "", "",Actuals!H10 + Strokes!G10) | H10: =if(Actuals!I10 = "", "",Actuals!I10 + Strokes!H10) | I10: =if(Actuals!J10 = "", "",Actuals!J10 + Strokes!I10) | ... Q10: =if(Actuals!R10 = "", "",Actuals!R10 + Strokes!Q10)
A11: =Actuals!B11 -> Danny C | B11: =if(Actuals!C11 = "", "",Actuals!C11 + Strokes!B11) | C11: =if(Actuals!D11 = "", "",Actuals!D11 + Strokes!C11) | D11: =if(Actuals!E11 = "", "",Actuals!E11 + Strokes!D11) | E11: =if(Actuals!F11 = "", "",Actuals!F11 + Strokes!E11) | F11: =if(Actuals!G11 = "", "",Actuals!G11 + Strokes!F11) | G11: =if(Actuals!H11 = "", "",Actuals!H11 + Strokes!G11) | H11: =if(Actuals!I11 = "", "",Actuals!I11 + Strokes!H11) | I11: =if(Actuals!J11 = "", "",Actuals!J11 + Strokes!I11) | ... Q11: =if(Actuals!R11 = "", "",Actuals!R11 + Strokes!Q11)
A12: =Actuals!B12 -> Eddie G | B12: =if(Actuals!C12 = "", "",Actuals!C12 + Strokes!B12) | C12: =if(Actuals!D12 = "", "",Actuals!D12 + Strokes!C12) | D12: =if(Actuals!E12 = "", "",Actuals!E12 + Strokes!D12) -> 44.5 | E12: =if(Actuals!F12 = "", "",Actuals!F12 + Strokes!E12) | F12: =if(Actuals!G12 = "", "",Actuals!G12 + Strokes!F12) | G12: =if(Actuals!H12 = "", "",Actuals!H12 + Strokes!G12) | H12: =if(Actuals!I12 = "", "",Actuals!I12 + Strokes!H12) | I12: =if(Actuals!J12 = "", "",Actuals!J12 + Strokes!I12) | ... Q12: =if(Actuals!R12 = "", "",Actuals!R12 + Strokes!Q12)
A13: =Actuals!B13 -> Grant G | B13: =if(Actuals!C13 = "", "",Actuals!C13 + Strokes!B13) | C13: =if(Actuals!D13 = "", "",Actuals!D13 + Strokes!C13) | D13: =if(Actuals!E13 = "", "",Actuals!E13 + Strokes!D13) | E13: =if(Actuals!F13 = "", "",Actuals!F13 + Strokes!E13) | F13: =if(Actuals!G13 = "", "",Actuals!G13 + Strokes!F13) | G13: =if(Actuals!H13 = "", "",Actuals!H13 + Strokes!G13) | H13: =if(Actuals!I13 = "", "",Actuals!I13 + Strokes!H13) | I13: =if(Actuals!J13 = "", "",Actuals!J13 + Strokes!I13) | ... Q13: =if(Actuals!R13 = "", "",Actuals!R13 + Strokes!Q13)
A14: =Actuals!B14 -> Jeff H | B14: =if(Actuals!C14 = "", "",Actuals!C14 + Strokes!B14) | C14: =if(Actuals!D14 = "", "",Actuals!D14 + Strokes!C14) | D14: =if(Actuals!E14 = "", "",Actuals!E14 + Strokes!D14) | E14: =if(Actuals!F14 = "", "",Actuals!F14 + Strokes!E14) | F14: =if(Actuals!G14 = "", "",Actuals!G14 + Strokes!F14) | G14: =if(Actuals!H14 = "", "",Actuals!H14 + Strokes!G14) | H14: =if(Actuals!I14 = "", "",Actuals!I14 + Strokes!H14) | I14: =if(Actuals!J14 = "", "",Actuals!J14 + Strokes!I14) | ... Q14: =if(Actuals!R14 = "", "",Actuals!R14 + Strokes!Q14)
A15: =Actuals!B15 -> Jenna T | B15: =if(Actuals!C15 = "", "",Actuals!C15 + Strokes!B15) | C15: =if(Actuals!D15 = "", "",Actuals!D15 + Strokes!C15) | D15: =if(Actuals!E15 = "", "",Actuals!E15 + Strokes!D15) | E15: =if(Actuals!F15 = "", "",Actuals!F15 + Strokes!E15) | F15: =if(Actuals!G15 = "", "",Actuals!G15 + Strokes!F15) | G15: =if(Actuals!H15 = "", "",Actuals!H15 + Strokes!G15) | H15: =if(Actuals!I15 = "", "",Actuals!I15 + Strokes!H15) | I15: =if(Actuals!J15 = "", "",Actuals!J15 + Strokes!I15) | ... Q15: =if(Actuals!R15 = "", "",Actuals!R15 + Strokes!Q15)
... A65: =Actuals!B65 -> blank21 | B65: =if(Actuals!C65 = "", "",Actuals!C65 + Strokes!B65) | C65: =if(Actuals!D65 = "", "",Actuals!D65 + Strokes!C65) | D65: =if(Actuals!E65 = "", "",Actuals!E65 + Strokes!D65) | E65: =if(Actuals!F65 = "", "",Actuals!F65 + Strokes!E65) | F65: =if(Actuals!G65 = "", "",Actuals!G65 + Strokes!F65) | G65: =if(Actuals!H65 = "", "",Actuals!H65 + Strokes!G65) | H65: =if(Actuals!I65 = "", "",Actuals!I65 + Strokes!H65) | I65: =if(Actuals!J65 = "", "",Actuals!J65 + Strokes!I65) | ... Q65: =if(Actuals!R65 = "", "",Actuals!R65 + Strokes!Q65)
A68: Low Net | B68: =min(B4:B64) -> 31.7 | C68: =min(C4:C64) -> 34.7 | D68: =min(D4:D64) -> 31.3 | E68: =min(E4:E64) -> 0 | F68: =min(F4:F64) -> 0 | G68: =min(G4:G64) -> 0 | H68: =min(H4:H64) -> 0 | I68: =min(I4:I64) -> 0 | ... Q68: =min(Q4:Q64) -> 0

Sheet Points
B1: 2026 Points
B2: 46094 | C2: 46100 | D2: =C2+7 -> 46107 | E2: =D2+7 -> 46114 | F2: =E2+7 -> 46121 | G2: =F2+7 -> 46128 | H2: =G2+7 -> 46135 | I2: =H2+7 -> 46142 | J2: =I2+7 -> 46149 | K2: =J2+7 -> 46156 | ... M2: =L2+7 -> 46170 | N2: 45848 | O2: =N2+7 -> 45855 | P2: =O2+7 -> 45862 | Q2: 45869
A3: Place Power | B3: 1 | C3: 1 | D3: 1 | E3: 1 | F3: 2 | G3: 1 | H3: 1 | I3: 1 | J3: 1 | K3: 1 | L3: 1 | M3: 1 | N3: 1 | O3: 1 | P3: 1 | Q3: 1
A4: Player | B4: Week 1 | C4: Week 2 | D4: Week 3 | E4: Week 4 | F4: Masters | G4: Week 6 | H4: Week 7 | I4: Week 8 | J4: Week 9 | K4: Week 10 | L4: Week 11 | M4: Week 12 | N4: Week 13 | O4: Week 14 | P4: Week 15 | Q4: Week 16 | R4: Total | S4: Rank | T4: Events | U4: P/E | V4: Wins | W4: Top 3's | X4: Top 5's | Y4: Strokes 2024 | AA4: Place | AB4: Points
A5: =Actuals!B4 -> Adrian C | B5: =if( Actuals!$A4=1,0,(IF(WeeklyRankPoints!B4 > 10,0,(IF(WeeklyRankPoints!B4 = 0,0,VLOOKUP(WeeklyRankPoints!B4,$AA$5:$AB$14,2))*B$3)) + IF(Actuals!C4 = "",0,10))) -> 0 | C5: =if( Actuals!$A4=1,0,(IF(WeeklyRankPoints!C4 > 10,0,(IF(WeeklyRankPoints!C4 = 0,0,VLOOKUP(WeeklyRankPoints!C4,$AA$5:$AB$14,2))*C$3)) + IF(Actuals!D4 = "",0,10))) -> 0 | D5: =if( Actuals!$A4=1,0,(IF(WeeklyRankPoints!D4 > 10,0,(IF(WeeklyRankPoints!D4 = 0,0,VLOOKUP(WeeklyRankPoints!D4,$AA$5:$AB$14,2))*D$3)) + IF(Actuals!E4 = "",0,10))) -> 0 | E5: =if( Actuals!$A4=1,0,(IF(WeeklyRankPoints!E4 > 10,0,(IF(WeeklyRankPoints!E4 = 0,0,VLOOKUP(WeeklyRankPoints!E4,$AA$5:$AB$14,2))*E$3)) + IF(Actuals!F4 = "",0,10))) -> 0 | F5: =if( Actuals!$A4=1,0,(IF(WeeklyRankPoints!F4 > 10,0,(IF(WeeklyRankPoints!F4 = 0,0,VLOOKUP(WeeklyRankPoints!F4,$AA$5:$AB$14,2))*F$3)) + IF(Actuals!G4 = "",0,10))) -> 0 | G5: =if( Actuals!$A4=1,0,(IF(WeeklyRankPoints!G4 > 10,0,(IF(WeeklyRankPoints!G4 = 0,0,VLOOKUP(WeeklyRankPoints!G4,$AA$5:$AB$14,2))*G$3)) + IF(Actuals!H4 = "",0,10))) -> 0 | H5: =if( Actuals!$A4=1,0,(IF(WeeklyRankPoints!H4 > 10,0,(IF(WeeklyRankPoints!H4 = 0,0,VLOOKUP(WeeklyRankPoints!H4,$AA$5:$AB$14,2))*H$3)) + IF(Actuals!I4 = "",0,10))) -> 0 | I5: =if( Actuals!$A4=1,0,(IF(WeeklyRankPoints!I4 > 10,0,(IF(WeeklyRankPoints!I4 = 0,0,VLOOKUP(WeeklyRankPoints!I4,$AA$5:$AB$14,2))*I$3)) + IF(Actuals!J4 = "",0,10))) -> 0 | ... Q5: =if( Actuals!$A4=1,0,(IF(WeeklyRankPoints!Q4 > 10,0,(IF(WeeklyRankPoints!Q4 = 0,0,VLOOKUP(WeeklyRankPoints!Q4,$AA$5:$AB$14,2))*Q$3)) + IF(Actuals!R4 = "",0,10))) -> 0 | R5: =SUM(B5:Q5) -> 0 | S5: =RANK(R5,R$5:R$66) -> 17 | T5: =COUNT(Actuals!C4:R4) -> 0 | U5: =IF(T5>0,R5/T5,0) -> 0 | V5: =WeeklyRankMoney!R4 -> 0 | W5: =WeeklyRankMoney!S4 -> 0 | X5: =WeeklyRankMoney!T4 -> 0 | Y5: =Strokes!Q4 -> -4.1 | AA5: 1 | AB5: 120 | AD5: 1 | AE5: 43181
A6: =Actuals!B5 -> Alan D | B6: =if( Actuals!$A5=1,0,(IF(WeeklyRankPoints!B5 > 10,0,(IF(WeeklyRankPoints!B5 = 0,0,VLOOKUP(WeeklyRankPoints!B5,$AA$5:$AB$14,2))*B$3)) + IF(Actuals!C5 = "",0,10))) -> 0 | C6: =if( Actuals!$A5=1,0,(IF(WeeklyRankPoints!C5 > 10,0,(IF(WeeklyRankPoints!C5 = 0,0,VLOOKUP(WeeklyRankPoints!C5,$AA$5:$AB$14,2))*C$3)) + IF(Actuals!D5 = "",0,10))) -> 0 | D6: =if( Actuals!$A5=1,0,(IF(WeeklyRankPoints!D5 > 10,0,(IF(WeeklyRankPoints!D5 = 0,0,VLOOKUP(WeeklyRankPoints!D5,$AA$5:$AB$14,2))*D$3)) + IF(Actuals!E5 = "",0,10))) -> 0 | E6: =if( Actuals!$A5=1,0,(IF(WeeklyRankPoints!E5 > 10,0,(IF(WeeklyRankPoints!E5 = 0,0,VLOOKUP(WeeklyRankPoints!E5,$AA$5:$AB$14,2))*E$3)) + IF(Actuals!F5 = "",0,10))) -> 0 | F6: =if( Actuals!$A5=1,0,(IF(WeeklyRankPoints!F5 > 10,0,(IF(WeeklyRankPoints!F5 = 0,0,VLOOKUP(WeeklyRankPoints!F5,$AA$5:$AB$14,2))*F$3)) + IF(Actuals!G5 = "",0,10))) -> 0 | G6: =if( Actuals!$A5=1,0,(IF(WeeklyRankPoints!G5 > 10,0,(IF(WeeklyRankPoints!G5 = 0,0,VLOOKUP(WeeklyRankPoints!G5,$AA$5:$AB$14,2))*G$3)) + IF(Actuals!H5 = "",0,10))) -> 0 | H6: =if( Actuals!$A5=1,0,(IF(WeeklyRankPoints!H5 > 10,0,(IF(WeeklyRankPoints!H5 = 0,0,VLOOKUP(WeeklyRankPoints!H5,$AA$5:$AB$14,2))*H$3)) + IF(Actuals!I5 = "",0,10))) -> 0 | I6: =if( Actuals!$A5=1,0,(IF(WeeklyRankPoints!I5 > 10,0,(IF(WeeklyRankPoints!I5 = 0,0,VLOOKUP(WeeklyRankPoints!I5,$AA$5:$AB$14,2))*I$3)) + IF(Actuals!J5 = "",0,10))) -> 0 | ... Q6: =if( Actuals!$A5=1,0,(IF(WeeklyRankPoints!Q5 > 10,0,(IF(WeeklyRankPoints!Q5 = 0,0,VLOOKUP(WeeklyRankPoints!Q5,$AA$5:$AB$14,2))*Q$3)) + IF(Actuals!R5 = "",0,10))) -> 0 | R6: =SUM(B6:Q6) -> 0 | S6: =RANK(R6,R$5:R$66) -> 17 | T6: =COUNT(Actuals!C5:R5) -> 0 | U6: =IF(T6>0,R6/T6,0) -> 0 | V6: =WeeklyRankMoney!R5 -> 0 | W6: =WeeklyRankMoney!S5 -> 0 | X6: =WeeklyRankMoney!T5 -> 0 | Y6: =Strokes!Q5 -> 0.8 | AA6: 2 | AB6: 90 | AD6: 2 | AE6: 43188
A7: =Actuals!B6 -> Baxter C | B7: =if( Actuals!$A6=1,0,(IF(WeeklyRankPoints!B6 > 10,0,(IF(WeeklyRankPoints!B6 = 0,0,VLOOKUP(WeeklyRankPoints!B6,$AA$5:$AB$14,2))*B$3)) + IF(Actuals!C6 = "",0,10))) -> 0 | C7: =if( Actuals!$A6=1,0,(IF(WeeklyRankPoints!C6 > 10,0,(IF(WeeklyRankPoints!C6 = 0,0,VLOOKUP(WeeklyRankPoints!C6,$AA$5:$AB$14,2))*C$3)) + IF(Actuals!D6 = "",0,10))) -> 0 | D7: =if( Actuals!$A6=1,0,(IF(WeeklyRankPoints!D6 > 10,0,(IF(WeeklyRankPoints!D6 = 0,0,VLOOKUP(WeeklyRankPoints!D6,$AA$5:$AB$14,2))*D$3)) + IF(Actuals!E6 = "",0,10))) -> 0 | E7: =if( Actuals!$A6=1,0,(IF(WeeklyRankPoints!E6 > 10,0,(IF(WeeklyRankPoints!E6 = 0,0,VLOOKUP(WeeklyRankPoints!E6,$AA$5:$AB$14,2))*E$3)) + IF(Actuals!F6 = "",0,10))) -> 0 | F7: =if( Actuals!$A6=1,0,(IF(WeeklyRankPoints!F6 > 10,0,(IF(WeeklyRankPoints!F6 = 0,0,VLOOKUP(WeeklyRankPoints!F6,$AA$5:$AB$14,2))*F$3)) + IF(Actuals!G6 = "",0,10))) -> 0 | G7: =if( Actuals!$A6=1,0,(IF(WeeklyRankPoints!G6 > 10,0,(IF(WeeklyRankPoints!G6 = 0,0,VLOOKUP(WeeklyRankPoints!G6,$AA$5:$AB$14,2))*G$3)) + IF(Actuals!H6 = "",0,10))) -> 0 | H7: =if( Actuals!$A6=1,0,(IF(WeeklyRankPoints!H6 > 10,0,(IF(WeeklyRankPoints!H6 = 0,0,VLOOKUP(WeeklyRankPoints!H6,$AA$5:$AB$14,2))*H$3)) + IF(Actuals!I6 = "",0,10))) -> 0 | I7: =if( Actuals!$A6=1,0,(IF(WeeklyRankPoints!I6 > 10,0,(IF(WeeklyRankPoints!I6 = 0,0,VLOOKUP(WeeklyRankPoints!I6,$AA$5:$AB$14,2))*I$3)) + IF(Actuals!J6 = "",0,10))) -> 0 | ... Q7: =if( Actuals!$A6=1,0,(IF(WeeklyRankPoints!Q6 > 10,0,(IF(WeeklyRankPoints!Q6 = 0,0,VLOOKUP(WeeklyRankPoints!Q6,$AA$5:$AB$14,2))*Q$3)) + IF(Actuals!R6 = "",0,10))) -> 0 | R7: =SUM(B7:Q7) -> 0 | S7: =RANK(R7,R$5:R$66) -> 17 | T7: =COUNT(Actuals!C6:R6) -> 0 | U7: =IF(T7>0,R7/T7,0) -> 0 | V7: =WeeklyRankMoney!R6 -> 0 | W7: =WeeklyRankMoney!S6 -> 0 | X7: =WeeklyRankMoney!T6 -> 0 | Y7: =Strokes!Q6 -> 0 | AA7: 3 | AB7: 65 | AD7: 3 | AE7: 43195
A8: =Actuals!B7 -> Bill Morton | B8: =if( Actuals!$A7=1,0,(IF(WeeklyRankPoints!B7 > 10,0,(IF(WeeklyRankPoints!B7 = 0,0,VLOOKUP(WeeklyRankPoints!B7,$AA$5:$AB$14,2))*B$3)) + IF(Actuals!C7 = "",0,10))) -> 0 | C8: =if( Actuals!$A7=1,0,(IF(WeeklyRankPoints!C7 > 10,0,(IF(WeeklyRankPoints!C7 = 0,0,VLOOKUP(WeeklyRankPoints!C7,$AA$5:$AB$14,2))*C$3)) + IF(Actuals!D7 = "",0,10))) -> 0 | D8: =if( Actuals!$A7=1,0,(IF(WeeklyRankPoints!D7 > 10,0,(IF(WeeklyRankPoints!D7 = 0,0,VLOOKUP(WeeklyRankPoints!D7,$AA$5:$AB$14,2))*D$3)) + IF(Actuals!E7 = "",0,10))) -> 0 | E8: =if( Actuals!$A7=1,0,(IF(WeeklyRankPoints!E7 > 10,0,(IF(WeeklyRankPoints!E7 = 0,0,VLOOKUP(WeeklyRankPoints!E7,$AA$5:$AB$14,2))*E$3)) + IF(Actuals!F7 = "",0,10))) -> 0 | F8: =if( Actuals!$A7=1,0,(IF(WeeklyRankPoints!F7 > 10,0,(IF(WeeklyRankPoints!F7 = 0,0,VLOOKUP(WeeklyRankPoints!F7,$AA$5:$AB$14,2))*F$3)) + IF(Actuals!G7 = "",0,10))) -> 0 | G8: =if( Actuals!$A7=1,0,(IF(WeeklyRankPoints!G7 > 10,0,(IF(WeeklyRankPoints!G7 = 0,0,VLOOKUP(WeeklyRankPoints!G7,$AA$5:$AB$14,2))*G$3)) + IF(Actuals!H7 = "",0,10))) -> 0 | H8: =if( Actuals!$A7=1,0,(IF(WeeklyRankPoints!H7 > 10,0,(IF(WeeklyRankPoints!H7 = 0,0,VLOOKUP(WeeklyRankPoints!H7,$AA$5:$AB$14,2))*H$3)) + IF(Actuals!I7 = "",0,10))) -> 0 | I8: =if( Actuals!$A7=1,0,(IF(WeeklyRankPoints!I7 > 10,0,(IF(WeeklyRankPoints!I7 = 0,0,VLOOKUP(WeeklyRankPoints!I7,$AA$5:$AB$14,2))*I$3)) + IF(Actuals!J7 = "",0,10))) -> 0 | ... Q8: =if( Actuals!$A7=1,0,(IF(WeeklyRankPoints!Q7 > 10,0,(IF(WeeklyRankPoints!Q7 = 0,0,VLOOKUP(WeeklyRankPoints!Q7,$AA$5:$AB$14,2))*Q$3)) + IF(Actuals!R7 = "",0,10))) -> 0 | R8: =SUM(B8:Q8) -> 0 | S8: =RANK(R8,R$5:R$66) -> 17 | T8: =COUNT(Actuals!C7:R7) -> 0 | U8: =IF(T8>0,R8/T8,0) -> 0 | V8: =WeeklyRankMoney!R7 -> 0 | W8: =WeeklyRankMoney!S7 -> 0 | X8: =WeeklyRankMoney!T7 -> 0 | Y8: =Strokes!Q7 -> -9.5 | AA8: 4 | AB8: 45 | AD8: 4 | AE8: 43202
A9: =Actuals!B8 -> Brian M | B9: =if( Actuals!$A8=1,0,(IF(WeeklyRankPoints!B8 > 10,0,(IF(WeeklyRankPoints!B8 = 0,0,VLOOKUP(WeeklyRankPoints!B8,$AA$5:$AB$14,2))*B$3)) + IF(Actuals!C8 = "",0,10))) -> 100 | C9: =if( Actuals!$A8=1,0,(IF(WeeklyRankPoints!C8 > 10,0,(IF(WeeklyRankPoints!C8 = 0,0,VLOOKUP(WeeklyRankPoints!C8,$AA$5:$AB$14,2))*C$3)) + IF(Actuals!D8 = "",0,10))) -> 130 | D9: =if( Actuals!$A8=1,0,(IF(WeeklyRankPoints!D8 > 10,0,(IF(WeeklyRankPoints!D8 = 0,0,VLOOKUP(WeeklyRankPoints!D8,$AA$5:$AB$14,2))*D$3)) + IF(Actuals!E8 = "",0,10))) -> 22 | E9: =if( Actuals!$A8=1,0,(IF(WeeklyRankPoints!E8 > 10,0,(IF(WeeklyRankPoints!E8 = 0,0,VLOOKUP(WeeklyRankPoints!E8,$AA$5:$AB$14,2))*E$3)) + IF(Actuals!F8 = "",0,10))) -> 0 | F9: =if( Actuals!$A8=1,0,(IF(WeeklyRankPoints!F8 > 10,0,(IF(WeeklyRankPoints!F8 = 0,0,VLOOKUP(WeeklyRankPoints!F8,$AA$5:$AB$14,2))*F$3)) + IF(Actuals!G8 = "",0,10))) -> 0 | G9: =if( Actuals!$A8=1,0,(IF(WeeklyRankPoints!G8 > 10,0,(IF(WeeklyRankPoints!G8 = 0,0,VLOOKUP(WeeklyRankPoints!G8,$AA$5:$AB$14,2))*G$3)) + IF(Actuals!H8 = "",0,10))) -> 0 | H9: =if( Actuals!$A8=1,0,(IF(WeeklyRankPoints!H8 > 10,0,(IF(WeeklyRankPoints!H8 = 0,0,VLOOKUP(WeeklyRankPoints!H8,$AA$5:$AB$14,2))*H$3)) + IF(Actuals!I8 = "",0,10))) -> 0 | I9: =if( Actuals!$A8=1,0,(IF(WeeklyRankPoints!I8 > 10,0,(IF(WeeklyRankPoints!I8 = 0,0,VLOOKUP(WeeklyRankPoints!I8,$AA$5:$AB$14,2))*I$3)) + IF(Actuals!J8 = "",0,10))) -> 0 | ... Q9: =if( Actuals!$A8=1,0,(IF(WeeklyRankPoints!Q8 > 10,0,(IF(WeeklyRankPoints!Q8 = 0,0,VLOOKUP(WeeklyRankPoints!Q8,$AA$5:$AB$14,2))*Q$3)) + IF(Actuals!R8 = "",0,10))) -> 0 | R9: =SUM(B9:Q9) -> 252 | S9: =RANK(R9,R$5:R$66) -> 1 | T9: =COUNT(Actuals!C8:R8) -> 3 | U9: =IF(T9>0,R9/T9,0) -> 84 | V9: =WeeklyRankMoney!R8 -> 1 | W9: =WeeklyRankMoney!S8 -> 2 | X9: =WeeklyRankMoney!T8 -> 2 | Y9: =Strokes!Q8 -> -3.5 | AA9: 5 | AB9: 30 | AD9: 5 | AE9: 43209
A10: =Actuals!B9 -> Bruce Marburger | B10: =if( Actuals!$A9=1,0,(IF(WeeklyRankPoints!B9 > 10,0,(IF(WeeklyRankPoints!B9 = 0,0,VLOOKUP(WeeklyRankPoints!B9,$AA$5:$AB$14,2))*B$3)) + IF(Actuals!C9 = "",0,10))) -> 16 | C10: =if( Actuals!$A9=1,0,(IF(WeeklyRankPoints!C9 > 10,0,(IF(WeeklyRankPoints!C9 = 0,0,VLOOKUP(WeeklyRankPoints!C9,$AA$5:$AB$14,2))*C$3)) + IF(Actuals!D9 = "",0,10))) -> 0 | D10: =if( Actuals!$A9=1,0,(IF(WeeklyRankPoints!D9 > 10,0,(IF(WeeklyRankPoints!D9 = 0,0,VLOOKUP(WeeklyRankPoints!D9,$AA$5:$AB$14,2))*D$3)) + IF(Actuals!E9 = "",0,10))) -> 0 | E10: =if( Actuals!$A9=1,0,(IF(WeeklyRankPoints!E9 > 10,0,(IF(WeeklyRankPoints!E9 = 0,0,VLOOKUP(WeeklyRankPoints!E9,$AA$5:$AB$14,2))*E$3)) + IF(Actuals!F9 = "",0,10))) -> 0 | F10: =if( Actuals!$A9=1,0,(IF(WeeklyRankPoints!F9 > 10,0,(IF(WeeklyRankPoints!F9 = 0,0,VLOOKUP(WeeklyRankPoints!F9,$AA$5:$AB$14,2))*F$3)) + IF(Actuals!G9 = "",0,10))) -> 0 | G10: =if( Actuals!$A9=1,0,(IF(WeeklyRankPoints!G9 > 10,0,(IF(WeeklyRankPoints!G9 = 0,0,VLOOKUP(WeeklyRankPoints!G9,$AA$5:$AB$14,2))*G$3)) + IF(Actuals!H9 = "",0,10))) -> 0 | H10: =if( Actuals!$A9=1,0,(IF(WeeklyRankPoints!H9 > 10,0,(IF(WeeklyRankPoints!H9 = 0,0,VLOOKUP(WeeklyRankPoints!H9,$AA$5:$AB$14,2))*H$3)) + IF(Actuals!I9 = "",0,10))) -> 0 | I10: =if( Actuals!$A9=1,0,(IF(WeeklyRankPoints!I9 > 10,0,(IF(WeeklyRankPoints!I9 = 0,0,VLOOKUP(WeeklyRankPoints!I9,$AA$5:$AB$14,2))*I$3)) + IF(Actuals!J9 = "",0,10))) -> 0 | ... Q10: =if( Actuals!$A9=1,0,(IF(WeeklyRankPoints!Q9 > 10,0,(IF(WeeklyRankPoints!Q9 = 0,0,VLOOKUP(WeeklyRankPoints!Q9,$AA$5:$AB$14,2))*Q$3)) + IF(Actuals!R9 = "",0,10))) -> 0 | R10: =SUM(B10:Q10) -> 16 | S10: =RANK(R10,R$5:R$66) -> 16 | T10: =COUNT(Actuals!C9:R9) -> 1 | U10: =IF(T10>0,R10/T10,0) -> 16 | V10: =WeeklyRankMoney!R9 -> 0 | W10: =WeeklyRankMoney!S9 -> 0 | X10: =WeeklyRankMoney!T9 -> 0 | Y10: =Strokes!Q9 -> -12.4 | AA10: 6 | AB10: 20 | AD10: 6 | AE10: 43216
A11: =Actuals!B10 -> Cole L | B11: =if( Actuals!$A10=1,0,(IF(WeeklyRankPoints!B10 > 10,0,(IF(WeeklyRankPoints!B10 = 0,0,VLOOKUP(WeeklyRankPoints!B10,$AA$5:$AB$14,2))*B$3)) + IF(Actuals!C10 = "",0,10))) -> 0 | C11: =if( Actuals!$A10=1,0,(IF(WeeklyRankPoints!C10 > 10,0,(IF(WeeklyRankPoints!C10 = 0,0,VLOOKUP(WeeklyRankPoints!C10,$AA$5:$AB$14,2))*C$3)) + IF(Actuals!D10 = "",0,10))) -> 0 | D11: =if( Actuals!$A10=1,0,(IF(WeeklyRankPoints!D10 > 10,0,(IF(WeeklyRankPoints!D10 = 0,0,VLOOKUP(WeeklyRankPoints!D10,$AA$5:$AB$14,2))*D$3)) + IF(Actuals!E10 = "",0,10))) -> 0 | E11: =if( Actuals!$A10=1,0,(IF(WeeklyRankPoints!E10 > 10,0,(IF(WeeklyRankPoints!E10 = 0,0,VLOOKUP(WeeklyRankPoints!E10,$AA$5:$AB$14,2))*E$3)) + IF(Actuals!F10 = "",0,10))) -> 0 | F11: =if( Actuals!$A10=1,0,(IF(WeeklyRankPoints!F10 > 10,0,(IF(WeeklyRankPoints!F10 = 0,0,VLOOKUP(WeeklyRankPoints!F10,$AA$5:$AB$14,2))*F$3)) + IF(Actuals!G10 = "",0,10))) -> 0 | G11: =if( Actuals!$A10=1,0,(IF(WeeklyRankPoints!G10 > 10,0,(IF(WeeklyRankPoints!G10 = 0,0,VLOOKUP(WeeklyRankPoints!G10,$AA$5:$AB$14,2))*G$3)) + IF(Actuals!H10 = "",0,10))) -> 0 | H11: =if( Actuals!$A10=1,0,(IF(WeeklyRankPoints!H10 > 10,0,(IF(WeeklyRankPoints!H10 = 0,0,VLOOKUP(WeeklyRankPoints!H10,$AA$5:$AB$14,2))*H$3)) + IF(Actuals!I10 = "",0,10))) -> 0 | I11: =if( Actuals!$A10=1,0,(IF(WeeklyRankPoints!I10 > 10,0,(IF(WeeklyRankPoints!I10 = 0,0,VLOOKUP(WeeklyRankPoints!I10,$AA$5:$AB$14,2))*I$3)) + IF(Actuals!J10 = "",0,10))) -> 0 | ... Q11: =if( Actuals!$A10=1,0,(IF(WeeklyRankPoints!Q10 > 10,0,(IF(WeeklyRankPoints!Q10 = 0,0,VLOOKUP(WeeklyRankPoints!Q10,$AA$5:$AB$14,2))*Q$3)) + IF(Actuals!R10 = "",0,10))) -> 0 | R11: =SUM(B11:Q11) -> 0 | S11: =RANK(R11,R$5:R$66) -> 17 | T11: =COUNT(Actuals!C10:R10) -> 0 | U11: =IF(T11>0,R11/T11,0) -> 0 | V11: =WeeklyRankMoney!R10 -> 0 | W11: =WeeklyRankMoney!S10 -> 0 | X11: =WeeklyRankMoney!T10 -> 0 | Y11: =Strokes!Q10 -> -2.8 | AA11: 7 | AB11: 16 | AD11: 7 | AE11: 43223
A12: =Actuals!B11 -> Danny C | B12: =if( Actuals!$A11=1,0,(IF(WeeklyRankPoints!B11 > 10,0,(IF(WeeklyRankPoints!B11 = 0,0,VLOOKUP(WeeklyRankPoints!B11,$AA$5:$AB$14,2))*B$3)) + IF(Actuals!C11 = "",0,10))) -> 0 | C12: =if( Actuals!$A11=1,0,(IF(WeeklyRankPoints!C11 > 10,0,(IF(WeeklyRankPoints!C11 = 0,0,VLOOKUP(WeeklyRankPoints!C11,$AA$5:$AB$14,2))*C$3)) + IF(Actuals!D11 = "",0,10))) -> 0 | D12: =if( Actuals!$A11=1,0,(IF(WeeklyRankPoints!D11 > 10,0,(IF(WeeklyRankPoints!D11 = 0,0,VLOOKUP(WeeklyRankPoints!D11,$AA$5:$AB$14,2))*D$3)) + IF(Actuals!E11 = "",0,10))) -> 0 | E12: =if( Actuals!$A11=1,0,(IF(WeeklyRankPoints!E11 > 10,0,(IF(WeeklyRankPoints!E11 = 0,0,VLOOKUP(WeeklyRankPoints!E11,$AA$5:$AB$14,2))*E$3)) + IF(Actuals!F11 = "",0,10))) -> 0 | F12: =if( Actuals!$A11=1,0,(IF(WeeklyRankPoints!F11 > 10,0,(IF(WeeklyRankPoints!F11 = 0,0,VLOOKUP(WeeklyRankPoints!F11,$AA$5:$AB$14,2))*F$3)) + IF(Actuals!G11 = "",0,10))) -> 0 | G12: =if( Actuals!$A11=1,0,(IF(WeeklyRankPoints!G11 > 10,0,(IF(WeeklyRankPoints!G11 = 0,0,VLOOKUP(WeeklyRankPoints!G11,$AA$5:$AB$14,2))*G$3)) + IF(Actuals!H11 = "",0,10))) -> 0 | H12: =if( Actuals!$A11=1,0,(IF(WeeklyRankPoints!H11 > 10,0,(IF(WeeklyRankPoints!H11 = 0,0,VLOOKUP(WeeklyRankPoints!H11,$AA$5:$AB$14,2))*H$3)) + IF(Actuals!I11 = "",0,10))) -> 0 | I12: =if( Actuals!$A11=1,0,(IF(WeeklyRankPoints!I11 > 10,0,(IF(WeeklyRankPoints!I11 = 0,0,VLOOKUP(WeeklyRankPoints!I11,$AA$5:$AB$14,2))*I$3)) + IF(Actuals!J11 = "",0,10))) -> 0 | ... Q12: =if( Actuals!$A11=1,0,(IF(WeeklyRankPoints!Q11 > 10,0,(IF(WeeklyRankPoints!Q11 = 0,0,VLOOKUP(WeeklyRankPoints!Q11,$AA$5:$AB$14,2))*Q$3)) + IF(Actuals!R11 = "",0,10))) -> 0 | R12: =SUM(B12:Q12) -> 0 | S12: =RANK(R12,R$5:R$66) -> 17 | T12: =COUNT(Actuals!C11:R11) -> 0 | U12: =IF(T12>0,R12/T12,0) -> 0 | V12: =WeeklyRankMoney!R11 -> 0 | W12: =WeeklyRankMoney!S11 -> 0 | X12: =WeeklyRankMoney!T11 -> 0 | Y12: =Strokes!Q11 -> -2.3 | AA12: 8 | AB12: 12 | AD12: 8 | AE12: 43230
A13: =Actuals!B12 -> Eddie G | B13: =if( Actuals!$A12=1,0,(IF(WeeklyRankPoints!B12 > 10,0,(IF(WeeklyRankPoints!B12 = 0,0,VLOOKUP(WeeklyRankPoints!B12,$AA$5:$AB$14,2))*B$3)) + IF(Actuals!C12 = "",0,10))) -> 0 | C13: =if( Actuals!$A12=1,0,(IF(WeeklyRankPoints!C12 > 10,0,(IF(WeeklyRankPoints!C12 = 0,0,VLOOKUP(WeeklyRankPoints!C12,$AA$5:$AB$14,2))*C$3)) + IF(Actuals!D12 = "",0,10))) -> 0 | D13: =if( Actuals!$A12=1,0,(IF(WeeklyRankPoints!D12 > 10,0,(IF(WeeklyRankPoints!D12 = 0,0,VLOOKUP(WeeklyRankPoints!D12,$AA$5:$AB$14,2))*D$3)) + IF(Actuals!E12 = "",0,10))) -> 0 | E13: =if( Actuals!$A12=1,0,(IF(WeeklyRankPoints!E12 > 10,0,(IF(WeeklyRankPoints!E12 = 0,0,VLOOKUP(WeeklyRankPoints!E12,$AA$5:$AB$14,2))*E$3)) + IF(Actuals!F12 = "",0,10))) -> 0 | F13: =if( Actuals!$A12=1,0,(IF(WeeklyRankPoints!F12 > 10,0,(IF(WeeklyRankPoints!F12 = 0,0,VLOOKUP(WeeklyRankPoints!F12,$AA$5:$AB$14,2))*F$3)) + IF(Actuals!G12 = "",0,10))) -> 0 | G13: =if( Actuals!$A12=1,0,(IF(WeeklyRankPoints!G12 > 10,0,(IF(WeeklyRankPoints!G12 = 0,0,VLOOKUP(WeeklyRankPoints!G12,$AA$5:$AB$14,2))*G$3)) + IF(Actuals!H12 = "",0,10))) -> 0 | H13: =if( Actuals!$A12=1,0,(IF(WeeklyRankPoints!H12 > 10,0,(IF(WeeklyRankPoints!H12 = 0,0,VLOOKUP(WeeklyRankPoints!H12,$AA$5:$AB$14,2))*H$3)) + IF(Actuals!I12 = "",0,10))) -> 0 | I13: =if( Actuals!$A12=1,0,(IF(WeeklyRankPoints!I12 > 10,0,(IF(WeeklyRankPoints!I12 = 0,0,VLOOKUP(WeeklyRankPoints!I12,$AA$5:$AB$14,2))*I$3)) + IF(Actuals!J12 = "",0,10))) -> 0 | ... Q13: =if( Actuals!$A12=1,0,(IF(WeeklyRankPoints!Q12 > 10,0,(IF(WeeklyRankPoints!Q12 = 0,0,VLOOKUP(WeeklyRankPoints!Q12,$AA$5:$AB$14,2))*Q$3)) + IF(Actuals!R12 = "",0,10))) -> 0 | R13: =SUM(B13:Q13) -> 0 | S13: =RANK(R13,R$5:R$66) -> 17 | T13: =COUNT(Actuals!C12:R12) -> 1 | U13: =IF(T13>0,R13/T13,0) -> 0 | V13: =WeeklyRankMoney!R12 -> 0 | W13: =WeeklyRankMoney!S12 -> 0 | X13: =WeeklyRankMoney!T12 -> 0 | Y13: =Strokes!Q12 -> -7.9 | AA13: 9 | AB13: 9 | AD13: 9 | AE13: 43237
A14: =Actuals!B13 -> Grant G | B14: =if( Actuals!$A13=1,0,(IF(WeeklyRankPoints!B13 > 10,0,(IF(WeeklyRankPoints!B13 = 0,0,VLOOKUP(WeeklyRankPoints!B13,$AA$5:$AB$14,2))*B$3)) + IF(Actuals!C13 = "",0,10))) -> 0 | C14: =if( Actuals!$A13=1,0,(IF(WeeklyRankPoints!C13 > 10,0,(IF(WeeklyRankPoints!C13 = 0,0,VLOOKUP(WeeklyRankPoints!C13,$AA$5:$AB$14,2))*C$3)) + IF(Actuals!D13 = "",0,10))) -> 0 | D14: =if( Actuals!$A13=1,0,(IF(WeeklyRankPoints!D13 > 10,0,(IF(WeeklyRankPoints!D13 = 0,0,VLOOKUP(WeeklyRankPoints!D13,$AA$5:$AB$14,2))*D$3)) + IF(Actuals!E13 = "",0,10))) -> 0 | E14: =if( Actuals!$A13=1,0,(IF(WeeklyRankPoints!E13 > 10,0,(IF(WeeklyRankPoints!E13 = 0,0,VLOOKUP(WeeklyRankPoints!E13,$AA$5:$AB$14,2))*E$3)) + IF(Actuals!F13 = "",0,10))) -> 0 | F14: =if( Actuals!$A13=1,0,(IF(WeeklyRankPoints!F13 > 10,0,(IF(WeeklyRankPoints!F13 = 0,0,VLOOKUP(WeeklyRankPoints!F13,$AA$5:$AB$14,2))*F$3)) + IF(Actuals!G13 = "",0,10))) -> 0 | G14: =if( Actuals!$A13=1,0,(IF(WeeklyRankPoints!G13 > 10,0,(IF(WeeklyRankPoints!G13 = 0,0,VLOOKUP(WeeklyRankPoints!G13,$AA$5:$AB$14,2))*G$3)) + IF(Actuals!H13 = "",0,10))) -> 0 | H14: =if( Actuals!$A13=1,0,(IF(WeeklyRankPoints!H13 > 10,0,(IF(WeeklyRankPoints!H13 = 0,0,VLOOKUP(WeeklyRankPoints!H13,$AA$5:$AB$14,2))*H$3)) + IF(Actuals!I13 = "",0,10))) -> 0 | I14: =if( Actuals!$A13=1,0,(IF(WeeklyRankPoints!I13 > 10,0,(IF(WeeklyRankPoints!I13 = 0,0,VLOOKUP(WeeklyRankPoints!I13,$AA$5:$AB$14,2))*I$3)) + IF(Actuals!J13 = "",0,10))) -> 0 | ... Q14: =if( Actuals!$A13=1,0,(IF(WeeklyRankPoints!Q13 > 10,0,(IF(WeeklyRankPoints!Q13 = 0,0,VLOOKUP(WeeklyRankPoints!Q13,$AA$5:$AB$14,2))*Q$3)) + IF(Actuals!R13 = "",0,10))) -> 0 | R14: =SUM(B14:Q14) -> 0 | S14: =RANK(R14,R$5:R$66) -> 17 | T14: =COUNT(Actuals!C13:R13) -> 0 | U14: =IF(T14>0,R14/T14,0) -> 0 | V14: =WeeklyRankMoney!R13 -> 0 | W14: =WeeklyRankMoney!S13 -> 0 | X14: =WeeklyRankMoney!T13 -> 0 | Y14: =Strokes!Q13 -> 0 | AA14: 10 | AB14: 6 | AD14: 10 | AE14: 43244
A15: =Actuals!B14 -> Jeff H | B15: =if( Actuals!$A14=1,0,(IF(WeeklyRankPoints!B14 > 10,0,(IF(WeeklyRankPoints!B14 = 0,0,VLOOKUP(WeeklyRankPoints!B14,$AA$5:$AB$14,2))*B$3)) + IF(Actuals!C14 = "",0,10))) -> 0 | C15: =if( Actuals!$A14=1,0,(IF(WeeklyRankPoints!C14 > 10,0,(IF(WeeklyRankPoints!C14 = 0,0,VLOOKUP(WeeklyRankPoints!C14,$AA$5:$AB$14,2))*C$3)) + IF(Actuals!D14 = "",0,10))) -> 0 | D15: =if( Actuals!$A14=1,0,(IF(WeeklyRankPoints!D14 > 10,0,(IF(WeeklyRankPoints!D14 = 0,0,VLOOKUP(WeeklyRankPoints!D14,$AA$5:$AB$14,2))*D$3)) + IF(Actuals!E14 = "",0,10))) -> 0 | E15: =if( Actuals!$A14=1,0,(IF(WeeklyRankPoints!E14 > 10,0,(IF(WeeklyRankPoints!E14 = 0,0,VLOOKUP(WeeklyRankPoints!E14,$AA$5:$AB$14,2))*E$3)) + IF(Actuals!F14 = "",0,10))) -> 0 | F15: =if( Actuals!$A14=1,0,(IF(WeeklyRankPoints!F14 > 10,0,(IF(WeeklyRankPoints!F14 = 0,0,VLOOKUP(WeeklyRankPoints!F14,$AA$5:$AB$14,2))*F$3)) + IF(Actuals!G14 = "",0,10))) -> 0 | G15: =if( Actuals!$A14=1,0,(IF(WeeklyRankPoints!G14 > 10,0,(IF(WeeklyRankPoints!G14 = 0,0,VLOOKUP(WeeklyRankPoints!G14,$AA$5:$AB$14,2))*G$3)) + IF(Actuals!H14 = "",0,10))) -> 0 | H15: =if( Actuals!$A14=1,0,(IF(WeeklyRankPoints!H14 > 10,0,(IF(WeeklyRankPoints!H14 = 0,0,VLOOKUP(WeeklyRankPoints!H14,$AA$5:$AB$14,2))*H$3)) + IF(Actuals!I14 = "",0,10))) -> 0 | I15: =if( Actuals!$A14=1,0,(IF(WeeklyRankPoints!I14 > 10,0,(IF(WeeklyRankPoints!I14 = 0,0,VLOOKUP(WeeklyRankPoints!I14,$AA$5:$AB$14,2))*I$3)) + IF(Actuals!J14 = "",0,10))) -> 0 | ... Q15: =if( Actuals!$A14=1,0,(IF(WeeklyRankPoints!Q14 > 10,0,(IF(WeeklyRankPoints!Q14 = 0,0,VLOOKUP(WeeklyRankPoints!Q14,$AA$5:$AB$14,2))*Q$3)) + IF(Actuals!R14 = "",0,10))) -> 0 | R15: =SUM(B15:Q15) -> 0 | S15: =RANK(R15,R$5:R$66) -> 17 | T15: =COUNT(Actuals!C14:R14) -> 0 | U15: =IF(T15>0,R15/T15,0) -> 0 | V15: =WeeklyRankMoney!R14 -> 0 | W15: =WeeklyRankMoney!S14 -> 0 | X15: =WeeklyRankMoney!T14 -> 0 | Y15: =Strokes!Q14 -> -12.5 | AD15: 11 | AE15: 43251
A16: =Actuals!B15 -> Jenna T | B16: =if( Actuals!$A15=1,0,(IF(WeeklyRankPoints!B15 > 10,0,(IF(WeeklyRankPoints!B15 = 0,0,VLOOKUP(WeeklyRankPoints!B15,$AA$5:$AB$14,2))*B$3)) + IF(Actuals!C15 = "",0,10))) -> 0 | C16: =if( Actuals!$A15=1,0,(IF(WeeklyRankPoints!C15 > 10,0,(IF(WeeklyRankPoints!C15 = 0,0,VLOOKUP(WeeklyRankPoints!C15,$AA$5:$AB$14,2))*C$3)) + IF(Actuals!D15 = "",0,10))) -> 0 | D16: =if( Actuals!$A15=1,0,(IF(WeeklyRankPoints!D15 > 10,0,(IF(WeeklyRankPoints!D15 = 0,0,VLOOKUP(WeeklyRankPoints!D15,$AA$5:$AB$14,2))*D$3)) + IF(Actuals!E15 = "",0,10))) -> 0 | E16: =if( Actuals!$A15=1,0,(IF(WeeklyRankPoints!E15 > 10,0,(IF(WeeklyRankPoints!E15 = 0,0,VLOOKUP(WeeklyRankPoints!E15,$AA$5:$AB$14,2))*E$3)) + IF(Actuals!F15 = "",0,10))) -> 0 | F16: =if( Actuals!$A15=1,0,(IF(WeeklyRankPoints!F15 > 10,0,(IF(WeeklyRankPoints!F15 = 0,0,VLOOKUP(WeeklyRankPoints!F15,$AA$5:$AB$14,2))*F$3)) + IF(Actuals!G15 = "",0,10))) -> 0 | G16: =if( Actuals!$A15=1,0,(IF(WeeklyRankPoints!G15 > 10,0,(IF(WeeklyRankPoints!G15 = 0,0,VLOOKUP(WeeklyRankPoints!G15,$AA$5:$AB$14,2))*G$3)) + IF(Actuals!H15 = "",0,10))) -> 0 | H16: =if( Actuals!$A15=1,0,(IF(WeeklyRankPoints!H15 > 10,0,(IF(WeeklyRankPoints!H15 = 0,0,VLOOKUP(WeeklyRankPoints!H15,$AA$5:$AB$14,2))*H$3)) + IF(Actuals!I15 = "",0,10))) -> 0 | I16: =if( Actuals!$A15=1,0,(IF(WeeklyRankPoints!I15 > 10,0,(IF(WeeklyRankPoints!I15 = 0,0,VLOOKUP(WeeklyRankPoints!I15,$AA$5:$AB$14,2))*I$3)) + IF(Actuals!J15 = "",0,10))) -> 0 | ... Q16: =if( Actuals!$A15=1,0,(IF(WeeklyRankPoints!Q15 > 10,0,(IF(WeeklyRankPoints!Q15 = 0,0,VLOOKUP(WeeklyRankPoints!Q15,$AA$5:$AB$14,2))*Q$3)) + IF(Actuals!R15 = "",0,10))) -> 0 | R16: =SUM(B16:Q16) -> 0 | S16: =RANK(R16,R$5:R$66) -> 17 | T16: =COUNT(Actuals!C15:R15) -> 0 | U16: =IF(T16>0,R16/T16,0) -> 0 | V16: =WeeklyRankMoney!R15 -> 0 | W16: =WeeklyRankMoney!S15 -> 0 | X16: =WeeklyRankMoney!T15 -> 0 | Y16: =Strokes!Q15 -> -5.6 | AD16: 12 | AE16: 43258
A17: =Actuals!B16 -> Jeremy H | B17: =if( Actuals!$A16=1,0,(IF(WeeklyRankPoints!B16 > 10,0,(IF(WeeklyRankPoints!B16 = 0,0,VLOOKUP(WeeklyRankPoints!B16,$AA$5:$AB$14,2))*B$3)) + IF(Actuals!C16 = "",0,10))) -> 0 | C17: =if( Actuals!$A16=1,0,(IF(WeeklyRankPoints!C16 > 10,0,(IF(WeeklyRankPoints!C16 = 0,0,VLOOKUP(WeeklyRankPoints!C16,$AA$5:$AB$14,2))*C$3)) + IF(Actuals!D16 = "",0,10))) -> 0 | D17: =if( Actuals!$A16=1,0,(IF(WeeklyRankPoints!D16 > 10,0,(IF(WeeklyRankPoints!D16 = 0,0,VLOOKUP(WeeklyRankPoints!D16,$AA$5:$AB$14,2))*D$3)) + IF(Actuals!E16 = "",0,10))) -> 0 | E17: =if( Actuals!$A16=1,0,(IF(WeeklyRankPoints!E16 > 10,0,(IF(WeeklyRankPoints!E16 = 0,0,VLOOKUP(WeeklyRankPoints!E16,$AA$5:$AB$14,2))*E$3)) + IF(Actuals!F16 = "",0,10))) -> 0 | F17: =if( Actuals!$A16=1,0,(IF(WeeklyRankPoints!F16 > 10,0,(IF(WeeklyRankPoints!F16 = 0,0,VLOOKUP(WeeklyRankPoints!F16,$AA$5:$AB$14,2))*F$3)) + IF(Actuals!G16 = "",0,10))) -> 0 | G17: =if( Actuals!$A16=1,0,(IF(WeeklyRankPoints!G16 > 10,0,(IF(WeeklyRankPoints!G16 = 0,0,VLOOKUP(WeeklyRankPoints!G16,$AA$5:$AB$14,2))*G$3)) + IF(Actuals!H16 = "",0,10))) -> 0 | H17: =if( Actuals!$A16=1,0,(IF(WeeklyRankPoints!H16 > 10,0,(IF(WeeklyRankPoints!H16 = 0,0,VLOOKUP(WeeklyRankPoints!H16,$AA$5:$AB$14,2))*H$3)) + IF(Actuals!I16 = "",0,10))) -> 0 | I17: =if( Actuals!$A16=1,0,(IF(WeeklyRankPoints!I16 > 10,0,(IF(WeeklyRankPoints!I16 = 0,0,VLOOKUP(WeeklyRankPoints!I16,$AA$5:$AB$14,2))*I$3)) + IF(Actuals!J16 = "",0,10))) -> 0 | ... Q17: =if( Actuals!$A16=1,0,(IF(WeeklyRankPoints!Q16 > 10,0,(IF(WeeklyRankPoints!Q16 = 0,0,VLOOKUP(WeeklyRankPoints!Q16,$AA$5:$AB$14,2))*Q$3)) + IF(Actuals!R16 = "",0,10))) -> 0 | R17: =SUM(B17:Q17) -> 0 | S17: =RANK(R17,R$5:R$66) -> 17 | T17: =COUNT(Actuals!C16:R16) -> 0 | U17: =IF(T17>0,R17/T17,0) -> 0 | V17: =WeeklyRankMoney!R16 -> 0 | W17: =WeeklyRankMoney!S16 -> 0 | X17: =WeeklyRankMoney!T16 -> 0 | Y17: =Strokes!Q16 -> -3.1 | AD17: 13 | AE17: 43265
A18: =Actuals!B17 -> Jeremy S | B18: =if( Actuals!$A17=1,0,(IF(WeeklyRankPoints!B17 > 10,0,(IF(WeeklyRankPoints!B17 = 0,0,VLOOKUP(WeeklyRankPoints!B17,$AA$5:$AB$14,2))*B$3)) + IF(Actuals!C17 = "",0,10))) -> 0 | C18: =if( Actuals!$A17=1,0,(IF(WeeklyRankPoints!C17 > 10,0,(IF(WeeklyRankPoints!C17 = 0,0,VLOOKUP(WeeklyRankPoints!C17,$AA$5:$AB$14,2))*C$3)) + IF(Actuals!D17 = "",0,10))) -> 0 | D18: =if( Actuals!$A17=1,0,(IF(WeeklyRankPoints!D17 > 10,0,(IF(WeeklyRankPoints!D17 = 0,0,VLOOKUP(WeeklyRankPoints!D17,$AA$5:$AB$14,2))*D$3)) + IF(Actuals!E17 = "",0,10))) -> 0 | E18: =if( Actuals!$A17=1,0,(IF(WeeklyRankPoints!E17 > 10,0,(IF(WeeklyRankPoints!E17 = 0,0,VLOOKUP(WeeklyRankPoints!E17,$AA$5:$AB$14,2))*E$3)) + IF(Actuals!F17 = "",0,10))) -> 0 | F18: =if( Actuals!$A17=1,0,(IF(WeeklyRankPoints!F17 > 10,0,(IF(WeeklyRankPoints!F17 = 0,0,VLOOKUP(WeeklyRankPoints!F17,$AA$5:$AB$14,2))*F$3)) + IF(Actuals!G17 = "",0,10))) -> 0 | G18: =if( Actuals!$A17=1,0,(IF(WeeklyRankPoints!G17 > 10,0,(IF(WeeklyRankPoints!G17 = 0,0,VLOOKUP(WeeklyRankPoints!G17,$AA$5:$AB$14,2))*G$3)) + IF(Actuals!H17 = "",0,10))) -> 0 | H18: =if( Actuals!$A17=1,0,(IF(WeeklyRankPoints!H17 > 10,0,(IF(WeeklyRankPoints!H17 = 0,0,VLOOKUP(WeeklyRankPoints!H17,$AA$5:$AB$14,2))*H$3)) + IF(Actuals!I17 = "",0,10))) -> 0 | I18: =if( Actuals!$A17=1,0,(IF(WeeklyRankPoints!I17 > 10,0,(IF(WeeklyRankPoints!I17 = 0,0,VLOOKUP(WeeklyRankPoints!I17,$AA$5:$AB$14,2))*I$3)) + IF(Actuals!J17 = "",0,10))) -> 0 | ... Q18: =if( Actuals!$A17=1,0,(IF(WeeklyRankPoints!Q17 > 10,0,(IF(WeeklyRankPoints!Q17 = 0,0,VLOOKUP(WeeklyRankPoints!Q17,$AA$5:$AB$14,2))*Q$3)) + IF(Actuals!R17 = "",0,10))) -> 0 | R18: =SUM(B18:Q18) -> 0 | S18: =RANK(R18,R$5:R$66) -> 17 | T18: =COUNT(Actuals!C17:R17) -> 0 | U18: =IF(T18>0,R18/T18,0) -> 0 | V18: =WeeklyRankMoney!R17 -> 0 | W18: =WeeklyRankMoney!S17 -> 0 | X18: =WeeklyRankMoney!T17 -> 0 | Y18: =Strokes!Q17 -> -10.7 | AD18: 14 | AE18: 43272
A19: =Actuals!B18 -> Jon L | B19: =if( Actuals!$A18=1,0,(IF(WeeklyRankPoints!B18 > 10,0,(IF(WeeklyRankPoints!B18 = 0,0,VLOOKUP(WeeklyRankPoints!B18,$AA$5:$AB$14,2))*B$3)) + IF(Actuals!C18 = "",0,10))) -> 10 | C19: =if( Actuals!$A18=1,0,(IF(WeeklyRankPoints!C18 > 10,0,(IF(WeeklyRankPoints!C18 = 0,0,VLOOKUP(WeeklyRankPoints!C18,$AA$5:$AB$14,2))*C$3)) + IF(Actuals!D18 = "",0,10))) -> 75 | D19: =if( Actuals!$A18=1,0,(IF(WeeklyRankPoints!D18 > 10,0,(IF(WeeklyRankPoints!D18 = 0,0,VLOOKUP(WeeklyRankPoints!D18,$AA$5:$AB$14,2))*D$3)) + IF(Actuals!E18 = "",0,10))) -> 22 | E19: =if( Actuals!$A18=1,0,(IF(WeeklyRankPoints!E18 > 10,0,(IF(WeeklyRankPoints!E18 = 0,0,VLOOKUP(WeeklyRankPoints!E18,$AA$5:$AB$14,2))*E$3)) + IF(Actuals!F18 = "",0,10))) -> 0 | F19: =if( Actuals!$A18=1,0,(IF(WeeklyRankPoints!F18 > 10,0,(IF(WeeklyRankPoints!F18 = 0,0,VLOOKUP(WeeklyRankPoints!F18,$AA$5:$AB$14,2))*F$3)) + IF(Actuals!G18 = "",0,10))) -> 0 | G19: =if( Actuals!$A18=1,0,(IF(WeeklyRankPoints!G18 > 10,0,(IF(WeeklyRankPoints!G18 = 0,0,VLOOKUP(WeeklyRankPoints!G18,$AA$5:$AB$14,2))*G$3)) + IF(Actuals!H18 = "",0,10))) -> 0 | H19: =if( Actuals!$A18=1,0,(IF(WeeklyRankPoints!H18 > 10,0,(IF(WeeklyRankPoints!H18 = 0,0,VLOOKUP(WeeklyRankPoints!H18,$AA$5:$AB$14,2))*H$3)) + IF(Actuals!I18 = "",0,10))) -> 0 | I19: =if( Actuals!$A18=1,0,(IF(WeeklyRankPoints!I18 > 10,0,(IF(WeeklyRankPoints!I18 = 0,0,VLOOKUP(WeeklyRankPoints!I18,$AA$5:$AB$14,2))*I$3)) + IF(Actuals!J18 = "",0,10))) -> 0 | ... Q19: =if( Actuals!$A18=1,0,(IF(WeeklyRankPoints!Q18 > 10,0,(IF(WeeklyRankPoints!Q18 = 0,0,VLOOKUP(WeeklyRankPoints!Q18,$AA$5:$AB$14,2))*Q$3)) + IF(Actuals!R18 = "",0,10))) -> 0 | R19: =SUM(B19:Q19) -> 107 | S19: =RANK(R19,R$5:R$66) -> 7 | T19: =COUNT(Actuals!C18:R18) -> 3 | U19: =IF(T19>0,R19/T19,0) -> 35.666667 | V19: =WeeklyRankMoney!R18 -> 0 | W19: =WeeklyRankMoney!S18 -> 1 | X19: =WeeklyRankMoney!T18 -> 1 | Y19: =Strokes!Q18 -> -6.7 | AD19: 15 | AE19: 43279
A20: =Actuals!B19 -> Jonah R | B20: =if( Actuals!$A19=1,0,(IF(WeeklyRankPoints!B19 > 10,0,(IF(WeeklyRankPoints!B19 = 0,0,VLOOKUP(WeeklyRankPoints!B19,$AA$5:$AB$14,2))*B$3)) + IF(Actuals!C19 = "",0,10))) -> 0 | C20: =if( Actuals!$A19=1,0,(IF(WeeklyRankPoints!C19 > 10,0,(IF(WeeklyRankPoints!C19 = 0,0,VLOOKUP(WeeklyRankPoints!C19,$AA$5:$AB$14,2))*C$3)) + IF(Actuals!D19 = "",0,10))) -> 40 | D20: =if( Actuals!$A19=1,0,(IF(WeeklyRankPoints!D19 > 10,0,(IF(WeeklyRankPoints!D19 = 0,0,VLOOKUP(WeeklyRankPoints!D19,$AA$5:$AB$14,2))*D$3)) + IF(Actuals!E19 = "",0,10))) -> 0 | E20: =if( Actuals!$A19=1,0,(IF(WeeklyRankPoints!E19 > 10,0,(IF(WeeklyRankPoints!E19 = 0,0,VLOOKUP(WeeklyRankPoints!E19,$AA$5:$AB$14,2))*E$3)) + IF(Actuals!F19 = "",0,10))) -> 0 | F20: =if( Actuals!$A19=1,0,(IF(WeeklyRankPoints!F19 > 10,0,(IF(WeeklyRankPoints!F19 = 0,0,VLOOKUP(WeeklyRankPoints!F19,$AA$5:$AB$14,2))*F$3)) + IF(Actuals!G19 = "",0,10))) -> 0 | G20: =if( Actuals!$A19=1,0,(IF(WeeklyRankPoints!G19 > 10,0,(IF(WeeklyRankPoints!G19 = 0,0,VLOOKUP(WeeklyRankPoints!G19,$AA$5:$AB$14,2))*G$3)) + IF(Actuals!H19 = "",0,10))) -> 0 | H20: =if( Actuals!$A19=1,0,(IF(WeeklyRankPoints!H19 > 10,0,(IF(WeeklyRankPoints!H19 = 0,0,VLOOKUP(WeeklyRankPoints!H19,$AA$5:$AB$14,2))*H$3)) + IF(Actuals!I19 = "",0,10))) -> 0 | I20: =if( Actuals!$A19=1,0,(IF(WeeklyRankPoints!I19 > 10,0,(IF(WeeklyRankPoints!I19 = 0,0,VLOOKUP(WeeklyRankPoints!I19,$AA$5:$AB$14,2))*I$3)) + IF(Actuals!J19 = "",0,10))) -> 0 | ... Q20: =if( Actuals!$A19=1,0,(IF(WeeklyRankPoints!Q19 > 10,0,(IF(WeeklyRankPoints!Q19 = 0,0,VLOOKUP(WeeklyRankPoints!Q19,$AA$5:$AB$14,2))*Q$3)) + IF(Actuals!R19 = "",0,10))) -> 0 | R20: =SUM(B20:Q20) -> 40 | S20: =RANK(R20,R$5:R$66) -> 14 | T20: =COUNT(Actuals!C19:R19) -> 1 | U20: =IF(T20>0,R20/T20,0) -> 40 | V20: =WeeklyRankMoney!R19 -> 0 | W20: =WeeklyRankMoney!S19 -> 0 | X20: =WeeklyRankMoney!T19 -> 1 | Y20: =Strokes!Q19 -> -9.6 | AD20: 16 | AE20: 43286
A21: =Actuals!B20 -> Jordan V | B21: =if( Actuals!$A20=1,0,(IF(WeeklyRankPoints!B20 > 10,0,(IF(WeeklyRankPoints!B20 = 0,0,VLOOKUP(WeeklyRankPoints!B20,$AA$5:$AB$14,2))*B$3)) + IF(Actuals!C20 = "",0,10))) -> 0 | C21: =if( Actuals!$A20=1,0,(IF(WeeklyRankPoints!C20 > 10,0,(IF(WeeklyRankPoints!C20 = 0,0,VLOOKUP(WeeklyRankPoints!C20,$AA$5:$AB$14,2))*C$3)) + IF(Actuals!D20 = "",0,10))) -> 0 | D21: =if( Actuals!$A20=1,0,(IF(WeeklyRankPoints!D20 > 10,0,(IF(WeeklyRankPoints!D20 = 0,0,VLOOKUP(WeeklyRankPoints!D20,$AA$5:$AB$14,2))*D$3)) + IF(Actuals!E20 = "",0,10))) -> 0 | E21: =if( Actuals!$A20=1,0,(IF(WeeklyRankPoints!E20 > 10,0,(IF(WeeklyRankPoints!E20 = 0,0,VLOOKUP(WeeklyRankPoints!E20,$AA$5:$AB$14,2))*E$3)) + IF(Actuals!F20 = "",0,10))) -> 0 | F21: =if( Actuals!$A20=1,0,(IF(WeeklyRankPoints!F20 > 10,0,(IF(WeeklyRankPoints!F20 = 0,0,VLOOKUP(WeeklyRankPoints!F20,$AA$5:$AB$14,2))*F$3)) + IF(Actuals!G20 = "",0,10))) -> 0 | G21: =if( Actuals!$A20=1,0,(IF(WeeklyRankPoints!G20 > 10,0,(IF(WeeklyRankPoints!G20 = 0,0,VLOOKUP(WeeklyRankPoints!G20,$AA$5:$AB$14,2))*G$3)) + IF(Actuals!H20 = "",0,10))) -> 0 | H21: =if( Actuals!$A20=1,0,(IF(WeeklyRankPoints!H20 > 10,0,(IF(WeeklyRankPoints!H20 = 0,0,VLOOKUP(WeeklyRankPoints!H20,$AA$5:$AB$14,2))*H$3)) + IF(Actuals!I20 = "",0,10))) -> 0 | I21: =if( Actuals!$A20=1,0,(IF(WeeklyRankPoints!I20 > 10,0,(IF(WeeklyRankPoints!I20 = 0,0,VLOOKUP(WeeklyRankPoints!I20,$AA$5:$AB$14,2))*I$3)) + IF(Actuals!J20 = "",0,10))) -> 0 | ... Q21: =if( Actuals!$A20=1,0,(IF(WeeklyRankPoints!Q20 > 10,0,(IF(WeeklyRankPoints!Q20 = 0,0,VLOOKUP(WeeklyRankPoints!Q20,$AA$5:$AB$14,2))*Q$3)) + IF(Actuals!R20 = "",0,10))) -> 0 | R21: =SUM(B21:Q21) -> 0 | S21: =RANK(R21,R$5:R$66) -> 17 | T21: =COUNT(Actuals!C20:R20) -> 0 | U21: =IF(T21>0,R21/T21,0) -> 0 | V21: =WeeklyRankMoney!R20 -> 0 | W21: =WeeklyRankMoney!S20 -> 0 | X21: =WeeklyRankMoney!T20 -> 0 | Y21: =Strokes!Q20 -> -1.1 | AD21: 17 | AE21: 43293
A22: =Actuals!B21 -> Kyle N | B22: =if( Actuals!$A21=1,0,(IF(WeeklyRankPoints!B21 > 10,0,(IF(WeeklyRankPoints!B21 = 0,0,VLOOKUP(WeeklyRankPoints!B21,$AA$5:$AB$14,2))*B$3)) + IF(Actuals!C21 = "",0,10))) -> 0 | C22: =if( Actuals!$A21=1,0,(IF(WeeklyRankPoints!C21 > 10,0,(IF(WeeklyRankPoints!C21 = 0,0,VLOOKUP(WeeklyRankPoints!C21,$AA$5:$AB$14,2))*C$3)) + IF(Actuals!D21 = "",0,10))) -> 0 | D22: =if( Actuals!$A21=1,0,(IF(WeeklyRankPoints!D21 > 10,0,(IF(WeeklyRankPoints!D21 = 0,0,VLOOKUP(WeeklyRankPoints!D21,$AA$5:$AB$14,2))*D$3)) + IF(Actuals!E21 = "",0,10))) -> 0 | E22: =if( Actuals!$A21=1,0,(IF(WeeklyRankPoints!E21 > 10,0,(IF(WeeklyRankPoints!E21 = 0,0,VLOOKUP(WeeklyRankPoints!E21,$AA$5:$AB$14,2))*E$3)) + IF(Actuals!F21 = "",0,10))) -> 0 | F22: =if( Actuals!$A21=1,0,(IF(WeeklyRankPoints!F21 > 10,0,(IF(WeeklyRankPoints!F21 = 0,0,VLOOKUP(WeeklyRankPoints!F21,$AA$5:$AB$14,2))*F$3)) + IF(Actuals!G21 = "",0,10))) -> 0 | G22: =if( Actuals!$A21=1,0,(IF(WeeklyRankPoints!G21 > 10,0,(IF(WeeklyRankPoints!G21 = 0,0,VLOOKUP(WeeklyRankPoints!G21,$AA$5:$AB$14,2))*G$3)) + IF(Actuals!H21 = "",0,10))) -> 0 | H22: =if( Actuals!$A21=1,0,(IF(WeeklyRankPoints!H21 > 10,0,(IF(WeeklyRankPoints!H21 = 0,0,VLOOKUP(WeeklyRankPoints!H21,$AA$5:$AB$14,2))*H$3)) + IF(Actuals!I21 = "",0,10))) -> 0 | I22: =if( Actuals!$A21=1,0,(IF(WeeklyRankPoints!I21 > 10,0,(IF(WeeklyRankPoints!I21 = 0,0,VLOOKUP(WeeklyRankPoints!I21,$AA$5:$AB$14,2))*I$3)) + IF(Actuals!J21 = "",0,10))) -> 0 | ... Q22: =if( Actuals!$A21=1,0,(IF(WeeklyRankPoints!Q21 > 10,0,(IF(WeeklyRankPoints!Q21 = 0,0,VLOOKUP(WeeklyRankPoints!Q21,$AA$5:$AB$14,2))*Q$3)) + IF(Actuals!R21 = "",0,10))) -> 0 | R22: =SUM(B22:Q22) -> 0 | S22: =RANK(R22,R$5:R$66) -> 17 | T22: =COUNT(Actuals!C21:R21) -> 3 | U22: =IF(T22>0,R22/T22,0) -> 0 | V22: =WeeklyRankMoney!R21 -> 1 | W22: =WeeklyRankMoney!S21 -> 1 | X22: =WeeklyRankMoney!T21 -> 1 | Y22: =Strokes!Q21 -> -3.7 | AD22: 18 | AE22: 43300
A23: =Actuals!B22 -> Laura L | B23: =if( Actuals!$A22=1,0,(IF(WeeklyRankPoints!B22 > 10,0,(IF(WeeklyRankPoints!B22 = 0,0,VLOOKUP(WeeklyRankPoints!B22,$AA$5:$AB$14,2))*B$3)) + IF(Actuals!C22 = "",0,10))) -> 0 | C23: =if( Actuals!$A22=1,0,(IF(WeeklyRankPoints!C22 > 10,0,(IF(WeeklyRankPoints!C22 = 0,0,VLOOKUP(WeeklyRankPoints!C22,$AA$5:$AB$14,2))*C$3)) + IF(Actuals!D22 = "",0,10))) -> 0 | D23: =if( Actuals!$A22=1,0,(IF(WeeklyRankPoints!D22 > 10,0,(IF(WeeklyRankPoints!D22 = 0,0,VLOOKUP(WeeklyRankPoints!D22,$AA$5:$AB$14,2))*D$3)) + IF(Actuals!E22 = "",0,10))) -> 0 | E23: =if( Actuals!$A22=1,0,(IF(WeeklyRankPoints!E22 > 10,0,(IF(WeeklyRankPoints!E22 = 0,0,VLOOKUP(WeeklyRankPoints!E22,$AA$5:$AB$14,2))*E$3)) + IF(Actuals!F22 = "",0,10))) -> 0 | F23: =if( Actuals!$A22=1,0,(IF(WeeklyRankPoints!F22 > 10,0,(IF(WeeklyRankPoints!F22 = 0,0,VLOOKUP(WeeklyRankPoints!F22,$AA$5:$AB$14,2))*F$3)) + IF(Actuals!G22 = "",0,10))) -> 0 | G23: =if( Actuals!$A22=1,0,(IF(WeeklyRankPoints!G22 > 10,0,(IF(WeeklyRankPoints!G22 = 0,0,VLOOKUP(WeeklyRankPoints!G22,$AA$5:$AB$14,2))*G$3)) + IF(Actuals!H22 = "",0,10))) -> 0 | H23: =if( Actuals!$A22=1,0,(IF(WeeklyRankPoints!H22 > 10,0,(IF(WeeklyRankPoints!H22 = 0,0,VLOOKUP(WeeklyRankPoints!H22,$AA$5:$AB$14,2))*H$3)) + IF(Actuals!I22 = "",0,10))) -> 0 | I23: =if( Actuals!$A22=1,0,(IF(WeeklyRankPoints!I22 > 10,0,(IF(WeeklyRankPoints!I22 = 0,0,VLOOKUP(WeeklyRankPoints!I22,$AA$5:$AB$14,2))*I$3)) + IF(Actuals!J22 = "",0,10))) -> 0 | ... Q23: =if( Actuals!$A22=1,0,(IF(WeeklyRankPoints!Q22 > 10,0,(IF(WeeklyRankPoints!Q22 = 0,0,VLOOKUP(WeeklyRankPoints!Q22,$AA$5:$AB$14,2))*Q$3)) + IF(Actuals!R22 = "",0,10))) -> 0 | R23: =SUM(B23:Q23) -> 0 | S23: =RANK(R23,R$5:R$66) -> 17 | T23: =COUNT(Actuals!C22:R22) -> 0 | U23: =IF(T23>0,R23/T23,0) -> 0 | V23: =WeeklyRankMoney!R22 -> 0 | W23: =WeeklyRankMoney!S22 -> 0 | X23: =WeeklyRankMoney!T22 -> 0 | Y23: =Strokes!Q22 -> -2.9
A24: =Actuals!B23 -> Luke W | B24: =if( Actuals!$A23=1,0,(IF(WeeklyRankPoints!B23 > 10,0,(IF(WeeklyRankPoints!B23 = 0,0,VLOOKUP(WeeklyRankPoints!B23,$AA$5:$AB$14,2))*B$3)) + IF(Actuals!C23 = "",0,10))) -> 0 | C24: =if( Actuals!$A23=1,0,(IF(WeeklyRankPoints!C23 > 10,0,(IF(WeeklyRankPoints!C23 = 0,0,VLOOKUP(WeeklyRankPoints!C23,$AA$5:$AB$14,2))*C$3)) + IF(Actuals!D23 = "",0,10))) -> 0 | D24: =if( Actuals!$A23=1,0,(IF(WeeklyRankPoints!D23 > 10,0,(IF(WeeklyRankPoints!D23 = 0,0,VLOOKUP(WeeklyRankPoints!D23,$AA$5:$AB$14,2))*D$3)) + IF(Actuals!E23 = "",0,10))) -> 130 | E24: =if( Actuals!$A23=1,0,(IF(WeeklyRankPoints!E23 > 10,0,(IF(WeeklyRankPoints!E23 = 0,0,VLOOKUP(WeeklyRankPoints!E23,$AA$5:$AB$14,2))*E$3)) + IF(Actuals!F23 = "",0,10))) -> 0 | F24: =if( Actuals!$A23=1,0,(IF(WeeklyRankPoints!F23 > 10,0,(IF(WeeklyRankPoints!F23 = 0,0,VLOOKUP(WeeklyRankPoints!F23,$AA$5:$AB$14,2))*F$3)) + IF(Actuals!G23 = "",0,10))) -> 0 | G24: =if( Actuals!$A23=1,0,(IF(WeeklyRankPoints!G23 > 10,0,(IF(WeeklyRankPoints!G23 = 0,0,VLOOKUP(WeeklyRankPoints!G23,$AA$5:$AB$14,2))*G$3)) + IF(Actuals!H23 = "",0,10))) -> 0 | H24: =if( Actuals!$A23=1,0,(IF(WeeklyRankPoints!H23 > 10,0,(IF(WeeklyRankPoints!H23 = 0,0,VLOOKUP(WeeklyRankPoints!H23,$AA$5:$AB$14,2))*H$3)) + IF(Actuals!I23 = "",0,10))) -> 0 | I24: =if( Actuals!$A23=1,0,(IF(WeeklyRankPoints!I23 > 10,0,(IF(WeeklyRankPoints!I23 = 0,0,VLOOKUP(WeeklyRankPoints!I23,$AA$5:$AB$14,2))*I$3)) + IF(Actuals!J23 = "",0,10))) -> 0 | ... Q24: =if( Actuals!$A23=1,0,(IF(WeeklyRankPoints!Q23 > 10,0,(IF(WeeklyRankPoints!Q23 = 0,0,VLOOKUP(WeeklyRankPoints!Q23,$AA$5:$AB$14,2))*Q$3)) + IF(Actuals!R23 = "",0,10))) -> 0 | R24: =SUM(B24:Q24) -> 130 | S24: =RANK(R24,R$5:R$66) -> 5 | T24: =COUNT(Actuals!C23:R23) -> 1 | U24: =IF(T24>0,R24/T24,0) -> 130 | V24: =WeeklyRankMoney!R23 -> 0 | W24: =WeeklyRankMoney!S23 -> 1 | X24: =WeeklyRankMoney!T23 -> 1 | Y24: =Strokes!Q23 -> -1
A25: =Actuals!B24 -> Marc C | B25: =if( Actuals!$A24=1,0,(IF(WeeklyRankPoints!B24 > 10,0,(IF(WeeklyRankPoints!B24 = 0,0,VLOOKUP(WeeklyRankPoints!B24,$AA$5:$AB$14,2))*B$3)) + IF(Actuals!C24 = "",0,10))) -> 130 | C25: =if( Actuals!$A24=1,0,(IF(WeeklyRankPoints!C24 > 10,0,(IF(WeeklyRankPoints!C24 = 0,0,VLOOKUP(WeeklyRankPoints!C24,$AA$5:$AB$14,2))*C$3)) + IF(Actuals!D24 = "",0,10))) -> 22 | D25: =if( Actuals!$A24=1,0,(IF(WeeklyRankPoints!D24 > 10,0,(IF(WeeklyRankPoints!D24 = 0,0,VLOOKUP(WeeklyRankPoints!D24,$AA$5:$AB$14,2))*D$3)) + IF(Actuals!E24 = "",0,10))) -> 0 | E25: =if( Actuals!$A24=1,0,(IF(WeeklyRankPoints!E24 > 10,0,(IF(WeeklyRankPoints!E24 = 0,0,VLOOKUP(WeeklyRankPoints!E24,$AA$5:$AB$14,2))*E$3)) + IF(Actuals!F24 = "",0,10))) -> 0 | F25: =if( Actuals!$A24=1,0,(IF(WeeklyRankPoints!F24 > 10,0,(IF(WeeklyRankPoints!F24 = 0,0,VLOOKUP(WeeklyRankPoints!F24,$AA$5:$AB$14,2))*F$3)) + IF(Actuals!G24 = "",0,10))) -> 0 | G25: =if( Actuals!$A24=1,0,(IF(WeeklyRankPoints!G24 > 10,0,(IF(WeeklyRankPoints!G24 = 0,0,VLOOKUP(WeeklyRankPoints!G24,$AA$5:$AB$14,2))*G$3)) + IF(Actuals!H24 = "",0,10))) -> 0 | H25: =if( Actuals!$A24=1,0,(IF(WeeklyRankPoints!H24 > 10,0,(IF(WeeklyRankPoints!H24 = 0,0,VLOOKUP(WeeklyRankPoints!H24,$AA$5:$AB$14,2))*H$3)) + IF(Actuals!I24 = "",0,10))) -> 0 | I25: =if( Actuals!$A24=1,0,(IF(WeeklyRankPoints!I24 > 10,0,(IF(WeeklyRankPoints!I24 = 0,0,VLOOKUP(WeeklyRankPoints!I24,$AA$5:$AB$14,2))*I$3)) + IF(Actuals!J24 = "",0,10))) -> 0 | ... Q25: =if( Actuals!$A24=1,0,(IF(WeeklyRankPoints!Q24 > 10,0,(IF(WeeklyRankPoints!Q24 = 0,0,VLOOKUP(WeeklyRankPoints!Q24,$AA$5:$AB$14,2))*Q$3)) + IF(Actuals!R24 = "",0,10))) -> 0 | R25: =SUM(B25:Q25) -> 152 | S25: =RANK(R25,R$5:R$66) -> 2 | T25: =COUNT(Actuals!C24:R24) -> 2 | U25: =IF(T25>0,R25/T25,0) -> 76 | V25: =WeeklyRankMoney!R24 -> 1 | W25: =WeeklyRankMoney!S24 -> 1 | X25: =WeeklyRankMoney!T24 -> 1 | Y25: =Strokes!Q24 -> -0.2
A26: =Actuals!B25 -> Mark M | B26: =if( Actuals!$A25=1,0,(IF(WeeklyRankPoints!B25 > 10,0,(IF(WeeklyRankPoints!B25 = 0,0,VLOOKUP(WeeklyRankPoints!B25,$AA$5:$AB$14,2))*B$3)) + IF(Actuals!C25 = "",0,10))) -> 26 | C26: =if( Actuals!$A25=1,0,(IF(WeeklyRankPoints!C25 > 10,0,(IF(WeeklyRankPoints!C25 = 0,0,VLOOKUP(WeeklyRankPoints!C25,$AA$5:$AB$14,2))*C$3)) + IF(Actuals!D25 = "",0,10))) -> 26 | D26: =if( Actuals!$A25=1,0,(IF(WeeklyRankPoints!D25 > 10,0,(IF(WeeklyRankPoints!D25 = 0,0,VLOOKUP(WeeklyRankPoints!D25,$AA$5:$AB$14,2))*D$3)) + IF(Actuals!E25 = "",0,10))) -> 26 | E26: =if( Actuals!$A25=1,0,(IF(WeeklyRankPoints!E25 > 10,0,(IF(WeeklyRankPoints!E25 = 0,0,VLOOKUP(WeeklyRankPoints!E25,$AA$5:$AB$14,2))*E$3)) + IF(Actuals!F25 = "",0,10))) -> 0 | F26: =if( Actuals!$A25=1,0,(IF(WeeklyRankPoints!F25 > 10,0,(IF(WeeklyRankPoints!F25 = 0,0,VLOOKUP(WeeklyRankPoints!F25,$AA$5:$AB$14,2))*F$3)) + IF(Actuals!G25 = "",0,10))) -> 0 | G26: =if( Actuals!$A25=1,0,(IF(WeeklyRankPoints!G25 > 10,0,(IF(WeeklyRankPoints!G25 = 0,0,VLOOKUP(WeeklyRankPoints!G25,$AA$5:$AB$14,2))*G$3)) + IF(Actuals!H25 = "",0,10))) -> 0 | H26: =if( Actuals!$A25=1,0,(IF(WeeklyRankPoints!H25 > 10,0,(IF(WeeklyRankPoints!H25 = 0,0,VLOOKUP(WeeklyRankPoints!H25,$AA$5:$AB$14,2))*H$3)) + IF(Actuals!I25 = "",0,10))) -> 0 | I26: =if( Actuals!$A25=1,0,(IF(WeeklyRankPoints!I25 > 10,0,(IF(WeeklyRankPoints!I25 = 0,0,VLOOKUP(WeeklyRankPoints!I25,$AA$5:$AB$14,2))*I$3)) + IF(Actuals!J25 = "",0,10))) -> 0 | ... Q26: =if( Actuals!$A25=1,0,(IF(WeeklyRankPoints!Q25 > 10,0,(IF(WeeklyRankPoints!Q25 = 0,0,VLOOKUP(WeeklyRankPoints!Q25,$AA$5:$AB$14,2))*Q$3)) + IF(Actuals!R25 = "",0,10))) -> 0 | R26: =SUM(B26:Q26) -> 78 | S26: =RANK(R26,R$5:R$66) -> 9 | T26: =COUNT(Actuals!C25:R25) -> 3 | U26: =IF(T26>0,R26/T26,0) -> 26 | V26: =WeeklyRankMoney!R25 -> 0 | W26: =WeeklyRankMoney!S25 -> 0 | X26: =WeeklyRankMoney!T25 -> 0 | Y26: =Strokes!Q25 -> -8
A27: =Actuals!B26 -> Martin R | B27: =if( Actuals!$A26=1,0,(IF(WeeklyRankPoints!B26 > 10,0,(IF(WeeklyRankPoints!B26 = 0,0,VLOOKUP(WeeklyRankPoints!B26,$AA$5:$AB$14,2))*B$3)) + IF(Actuals!C26 = "",0,10))) -> 0 | C27: =if( Actuals!$A26=1,0,(IF(WeeklyRankPoints!C26 > 10,0,(IF(WeeklyRankPoints!C26 = 0,0,VLOOKUP(WeeklyRankPoints!C26,$AA$5:$AB$14,2))*C$3)) + IF(Actuals!D26 = "",0,10))) -> 0 | D27: =if( Actuals!$A26=1,0,(IF(WeeklyRankPoints!D26 > 10,0,(IF(WeeklyRankPoints!D26 = 0,0,VLOOKUP(WeeklyRankPoints!D26,$AA$5:$AB$14,2))*D$3)) + IF(Actuals!E26 = "",0,10))) -> 0 | E27: =if( Actuals!$A26=1,0,(IF(WeeklyRankPoints!E26 > 10,0,(IF(WeeklyRankPoints!E26 = 0,0,VLOOKUP(WeeklyRankPoints!E26,$AA$5:$AB$14,2))*E$3)) + IF(Actuals!F26 = "",0,10))) -> 0 | F27: =if( Actuals!$A26=1,0,(IF(WeeklyRankPoints!F26 > 10,0,(IF(WeeklyRankPoints!F26 = 0,0,VLOOKUP(WeeklyRankPoints!F26,$AA$5:$AB$14,2))*F$3)) + IF(Actuals!G26 = "",0,10))) -> 0 | G27: =if( Actuals!$A26=1,0,(IF(WeeklyRankPoints!G26 > 10,0,(IF(WeeklyRankPoints!G26 = 0,0,VLOOKUP(WeeklyRankPoints!G26,$AA$5:$AB$14,2))*G$3)) + IF(Actuals!H26 = "",0,10))) -> 0 | H27: =if( Actuals!$A26=1,0,(IF(WeeklyRankPoints!H26 > 10,0,(IF(WeeklyRankPoints!H26 = 0,0,VLOOKUP(WeeklyRankPoints!H26,$AA$5:$AB$14,2))*H$3)) + IF(Actuals!I26 = "",0,10))) -> 0 | I27: =if( Actuals!$A26=1,0,(IF(WeeklyRankPoints!I26 > 10,0,(IF(WeeklyRankPoints!I26 = 0,0,VLOOKUP(WeeklyRankPoints!I26,$AA$5:$AB$14,2))*I$3)) + IF(Actuals!J26 = "",0,10))) -> 0 | ... Q27: =if( Actuals!$A26=1,0,(IF(WeeklyRankPoints!Q26 > 10,0,(IF(WeeklyRankPoints!Q26 = 0,0,VLOOKUP(WeeklyRankPoints!Q26,$AA$5:$AB$14,2))*Q$3)) + IF(Actuals!R26 = "",0,10))) -> 0 | R27: =SUM(B27:Q27) -> 0 | S27: =RANK(R27,R$5:R$66) -> 17 | T27: =COUNT(Actuals!C26:R26) -> 0 | U27: =IF(T27>0,R27/T27,0) -> 0 | V27: =WeeklyRankMoney!R26 -> 0 | W27: =WeeklyRankMoney!S26 -> 0 | X27: =WeeklyRankMoney!T26 -> 0 | Y27: =Strokes!Q26 -> -7.8
A28: =Actuals!B27 -> Minji S | B28: =if( Actuals!$A27=1,0,(IF(WeeklyRankPoints!B27 > 10,0,(IF(WeeklyRankPoints!B27 = 0,0,VLOOKUP(WeeklyRankPoints!B27,$AA$5:$AB$14,2))*B$3)) + IF(Actuals!C27 = "",0,10))) -> 0 | C28: =if( Actuals!$A27=1,0,(IF(WeeklyRankPoints!C27 > 10,0,(IF(WeeklyRankPoints!C27 = 0,0,VLOOKUP(WeeklyRankPoints!C27,$AA$5:$AB$14,2))*C$3)) + IF(Actuals!D27 = "",0,10))) -> 0 | D28: =if( Actuals!$A27=1,0,(IF(WeeklyRankPoints!D27 > 10,0,(IF(WeeklyRankPoints!D27 = 0,0,VLOOKUP(WeeklyRankPoints!D27,$AA$5:$AB$14,2))*D$3)) + IF(Actuals!E27 = "",0,10))) -> 0 | E28: =if( Actuals!$A27=1,0,(IF(WeeklyRankPoints!E27 > 10,0,(IF(WeeklyRankPoints!E27 = 0,0,VLOOKUP(WeeklyRankPoints!E27,$AA$5:$AB$14,2))*E$3)) + IF(Actuals!F27 = "",0,10))) -> 0 | F28: =if( Actuals!$A27=1,0,(IF(WeeklyRankPoints!F27 > 10,0,(IF(WeeklyRankPoints!F27 = 0,0,VLOOKUP(WeeklyRankPoints!F27,$AA$5:$AB$14,2))*F$3)) + IF(Actuals!G27 = "",0,10))) -> 0 | G28: =if( Actuals!$A27=1,0,(IF(WeeklyRankPoints!G27 > 10,0,(IF(WeeklyRankPoints!G27 = 0,0,VLOOKUP(WeeklyRankPoints!G27,$AA$5:$AB$14,2))*G$3)) + IF(Actuals!H27 = "",0,10))) -> 0 | H28: =if( Actuals!$A27=1,0,(IF(WeeklyRankPoints!H27 > 10,0,(IF(WeeklyRankPoints!H27 = 0,0,VLOOKUP(WeeklyRankPoints!H27,$AA$5:$AB$14,2))*H$3)) + IF(Actuals!I27 = "",0,10))) -> 0 | I28: =if( Actuals!$A27=1,0,(IF(WeeklyRankPoints!I27 > 10,0,(IF(WeeklyRankPoints!I27 = 0,0,VLOOKUP(WeeklyRankPoints!I27,$AA$5:$AB$14,2))*I$3)) + IF(Actuals!J27 = "",0,10))) -> 0 | ... Q28: =if( Actuals!$A27=1,0,(IF(WeeklyRankPoints!Q27 > 10,0,(IF(WeeklyRankPoints!Q27 = 0,0,VLOOKUP(WeeklyRankPoints!Q27,$AA$5:$AB$14,2))*Q$3)) + IF(Actuals!R27 = "",0,10))) -> 0 | R28: =SUM(B28:Q28) -> 0 | S28: =RANK(R28,R$5:R$66) -> 17 | T28: =COUNT(Actuals!C27:R27) -> 0 | U28: =IF(T28>0,R28/T28,0) -> 0 | V28: =WeeklyRankMoney!R27 -> 0 | W28: =WeeklyRankMoney!S27 -> 0 | X28: =WeeklyRankMoney!T27 -> 0 | Y28: =Strokes!Q27 -> -12.9
